Workbook

Sheet KEEPER LLM Sensitivity All
A1: Model
A2: Label | C2: GPT 5o | D2: % | E2: Copilot 4o | F2: % | G2: Copilot 5o | H2: % | I2: Gemini | J2: %
B3: No Case | C3: 18 | D3: =C3/81 -> 0.22222222 | E3: 21 | F3: =E3/81 -> 0.25925926 | G3: 11 | H3: =G3/81 -> 0.13580247 | I3: 4 | J3: =I3/81 -> 0.049382716
B4: Probable | C4: 63 | D4: =C4/81 -> 0.77777778 | E4: 60 | F4: =E4/81 -> 0.74074074 | G4: 50 | H4: =G4/91 -> 0.54945055 | I4: 47 | J4: =I4/81 -> 0.58024691
B5: Case | C5: 0 | D5: =C5/81 -> 0 | E5: 0 | F5: =E5/81 -> 0 | G5: 20 | H5: =G5/81 -> 0.24691358 | I5: 30 | J5: =I5/81 -> 0.37037037

Sheet All by All
A1: personId | B1: Clinician | C1: GPT 5o | D1: Copilot 4o | E1: Copilot 5o | F1: Gemini
A2: 7810823 | B2: =INDEX(Clinician!S:S,MATCH('All by All'!A2,Clinician!A:A,0)) -> CASE (complications + treatment) | C2: =INDEX('GPT 5o'!T:T,MATCH('All by All'!A2,'GPT 5o'!B:B,0)) -> Probable | D2: =INDEX('Copilot 4o'!A:A,MATCH('All by All'!A2,'Copilot 4o'!B:B,0)) -> Probable (Treatment Only) | E2: =INDEX('Copilot 5o'!A:A,MATCH('All by All'!A2,'Copilot 5o'!B:B,0)) -> Probable (Treatment Only) | F2: =INDEX(Gemini!A:A,MATCH('All by All'!A2,Gemini!B:B,0)) -> Case (Symptom+Treatment)
A3: 2352010389 | B3: =INDEX(Clinician!S:S,MATCH('All by All'!A3,Clinician!A:A,0)) -> CASE (complications + treatment) | C3: =INDEX('GPT 5o'!T:T,MATCH('All by All'!A3,'GPT 5o'!B:B,0)) -> Probable | D3: =INDEX('Copilot 4o'!A:A,MATCH('All by All'!A3,'Copilot 4o'!B:B,0)) -> Probable (Treatment Only) | E3: =INDEX('Copilot 5o'!A:A,MATCH('All by All'!A3,'Copilot 5o'!B:B,0)) -> Case (Symptom+Treatment) | F3: =INDEX(Gemini!A:A,MATCH('All by All'!A3,Gemini!B:B,0)) -> Case (Symptom+Treatment)
A4: 244010017 | B4: =INDEX(Clinician!S:S,MATCH('All by All'!A4,Clinician!A:A,0)) -> CASE (complications + treatment) | C4: =INDEX('GPT 5o'!T:T,MATCH('All by All'!A4,'GPT 5o'!B:B,0)) -> Probable | D4: =INDEX('Copilot 4o'!A:A,MATCH('All by All'!A4,'Copilot 4o'!B:B,0)) -> Probable (Treatment Only) | E4: =INDEX('Copilot 5o'!A:A,MATCH('All by All'!A4,'Copilot 5o'!B:B,0)) -> Case (Symptom+Treatment) | F4: =INDEX(Gemini!A:A,MATCH('All by All'!A4,Gemini!B:B,0)) -> Probable (Treatment Only)
A5: 5359010662 | B5: =INDEX(Clinician!S:S,MATCH('All by All'!A5,Clinician!A:A,0)) -> PROBABLE (treatment only) | C5: =INDEX('GPT 5o'!T:T,MATCH('All by All'!A5,'GPT 5o'!B:B,0)) -> Probable | D5: =INDEX('Copilot 4o'!A:A,MATCH('All by All'!A5,'Copilot 4o'!B:B,0)) -> Probable (Treatment Only) | E5: =INDEX('Copilot 5o'!A:A,MATCH('All by All'!A5,'Copilot 5o'!B:B,0)) -> Case (Symptom+Treatment) | F5: =INDEX(Gemini!A:A,MATCH('All by All'!A5,Gemini!B:B,0)) -> Case (Symptom+Treatment)
A6: 261610479 | B6: =INDEX(Clinician!S:S,MATCH('All by All'!A6,Clinician!A:A,0)) -> PROBABLE (treatment only) | C6: =INDEX('GPT 5o'!T:T,MATCH('All by All'!A6,'GPT 5o'!B:B,0)) -> Probable | D6: =INDEX('Copilot 4o'!A:A,MATCH('All by All'!A6,'Copilot 4o'!B:B,0)) -> Probable (Treatment Only) | E6: =INDEX('Copilot 5o'!A:A,MATCH('All by All'!A6,'Copilot 5o'!B:B,0)) -> Probable (Treatment Only) | F6: =INDEX(Gemini!A:A,MATCH('All by All'!A6,Gemini!B:B,0)) -> Case (Symptom+Treatment)
A7: 378410775 | B7: =INDEX(Clinician!S:S,MATCH('All by All'!A7,Clinician!A:A,0)) -> CASE (complications + treatment) | C7: =INDEX('GPT 5o'!T:T,MATCH('All by All'!A7,'GPT 5o'!B:B,0)) -> No Case | D7: =INDEX('Copilot 4o'!A:A,MATCH('All by All'!A7,'Copilot 4o'!B:B,0)) -> No | E7: =INDEX('Copilot 5o'!A:A,MATCH('All by All'!A7,'Copilot 5o'!B:B,0)) -> Probable (Treatment Only) | F7: =INDEX(Gemini!A:A,MATCH('All by All'!A7,Gemini!B:B,0)) -> Probable (Treatment Only)
A8: 1502010397 | B8: =INDEX(Clinician!S:S,MATCH('All by All'!A8,Clinician!A:A,0)) -> PROBABLE (treatment only) | C8: =INDEX('GPT 5o'!T:T,MATCH('All by All'!A8,'GPT 5o'!B:B,0)) -> Probable | D8: =INDEX('Copilot 4o'!A:A,MATCH('All by All'!A8,'Copilot 4o'!B:B,0)) -> Probable (Treatment Only) | E8: =INDEX('Copilot 5o'!A:A,MATCH('All by All'!A8,'Copilot 5o'!B:B,0)) -> Probable (Treatment Only) | F8: =INDEX(Gemini!A:A,MATCH('All by All'!A8,Gemini!B:B,0)) -> Probable (Treatment Only)
A9: 2353710622 | B9: =INDEX(Clinician!S:S,MATCH('All by All'!A9,Clinician!A:A,0)) -> PROBABLE (treatment only) | C9: =INDEX('GPT 5o'!T:T,MATCH('All by All'!A9,'GPT 5o'!B:B,0)) -> Probable | D9: =INDEX('Copilot 4o'!A:A,MATCH('All by All'!A9,'Copilot 4o'!B:B,0)) -> Probable (Treatment Only) | E9: =INDEX('Copilot 5o'!A:A,MATCH('All by All'!A9,'Copilot 5o'!B:B,0)) -> Probable (Treatment Only) | F9: =INDEX(Gemini!A:A,MATCH('All by All'!A9,Gemini!B:B,0)) -> Case (Symptom+Treatment)
A10: 1045410614 | B10: =INDEX(Clinician!S:S,MATCH('All by All'!A10,Clinician!A:A,0)) -> CASE (complications + treatment) | C10: =INDEX('GPT 5o'!T:T,MATCH('All by All'!A10,'GPT 5o'!B:B,0)) -> Probable | D10: =INDEX('Copilot 4o'!A:A,MATCH('All by All'!A10,'Copilot 4o'!B:B,0)) -> Probable (Treatment Only) | E10: =INDEX('Copilot 5o'!A:A,MATCH('All by All'!A10,'Copilot 5o'!B:B,0)) -> Probable (Treatment Only) | F10: =INDEX(Gemini!A:A,MATCH('All by All'!A10,Gemini!B:B,0)) -> Probable (Treatment Only)
A11: 4803410866 | B11: =INDEX(Clinician!S:S,MATCH('All by All'!A11,Clinician!A:A,0)) -> PROBABLE (treatment only) | C11: =INDEX('GPT 5o'!T:T,MATCH('All by All'!A11,'GPT 5o'!B:B,0)) -> No Case | D11: =INDEX('Copilot 4o'!A:A,MATCH('All by All'!A11,'Copilot 4o'!B:B,0)) -> No | E11: =INDEX('Copilot 5o'!A:A,MATCH('All by All'!A11,'Copilot 5o'!B:B,0)) -> Probable (Treatment Only) | F11: =INDEX(Gemini!A:A,MATCH('All by All'!A11,Gemini!B:B,0)) -> Probable (Treatment Only)
A12: 384210994 | B12: =INDEX(Clinician!S:S,MATCH('All by All'!A12,Clinician!A:A,0)) -> PROBABLE (treatment only) | C12: =INDEX('GPT 5o'!T:T,MATCH('All by All'!A12,'GPT 5o'!B:B,0)) -> Probable | D12: =INDEX('Copilot 4o'!A:A,MATCH('All by All'!A12,'Copilot 4o'!B:B,0)) -> Probable (Treatment Only) | E12: =INDEX('Copilot 5o'!A:A,MATCH('All by All'!A12,'Copilot 5o'!B:B,0)) -> Probable (Treatment Only) | F12: =INDEX(Gemini!A:A,MATCH('All by All'!A12,Gemini!B:B,0)) -> Probable (Treatment Only)
A13: 77110497 | B13: =INDEX(Clinician!S:S,MATCH('All by All'!A13,Clinician!A:A,0)) -> CASE (complications + treatment) | C13: =INDEX('GPT 5o'!T:T,MATCH('All by All'!A13,'GPT 5o'!B:B,0)) -> Probable | D13: =INDEX('Copilot 4o'!A:A,MATCH('All by All'!A13,'Copilot 4o'!B:B,0)) -> No | E13: =INDEX('Copilot 5o'!A:A,MATCH('All by All'!A13,'Copilot 5o'!B:B,0)) -> Probable (Treatment Only) | F13: =INDEX(Gemini!A:A,MATCH('All by All'!A13,Gemini!B:B,0)) -> Probable (Treatment Only)
... A82: 9461110544 | B82: =INDEX(Clinician!S:S,MATCH('All by All'!A82,Clinician!A:A,0)) -> PROBABLE (treatment only) | C82: =INDEX('GPT 5o'!T:T,MATCH('All by All'!A82,'GPT 5o'!B:B,0)) -> Probable | D82: =INDEX('Copilot 4o'!A:A,MATCH('All by All'!A82,'Copilot 4o'!B:B,0)) -> Probable (Treatment Only) | E82: =INDEX('Copilot 5o'!A:A,MATCH('All by All'!A82,'Copilot 5o'!B:B,0)) -> Probable (Treatment Only) | F82: =INDEX(Gemini!A:A,MATCH('All by All'!A82,Gemini!B:B,0)) -> Probable (Treatment Only)

Sheet Clinician
A1: personId | B1: age | C1: gender | D1: observationPeriod | E1: visitContext | F1: presentation (day 0) | G1: comorbidities (day 0) | H1: symptoms (day 0) | I1: priorDisease (before day 0) | J1: priorDrugs (before day 0) | K1: priorTreatmentProcedures (before day 0) | L1: diagnosticProcedures (before and after day 0) | M1: measurements (before and after day 0) | N1: alternativeDiagnosis (after day 0) | O1: afterDisease (after day 0) | P1: afterTreatmentProcedures (after day 0) | Q1: afterDrugs (after day 0) | R1: death | S1: DANI_CLASSIFICATION | T1: COMMENTS
A2: 7810823 | B2: 53 | C2: Female | D2: -2979 days - 4196 days | E2: Office Visit->Office Visit | F2: 10g monofilament sensation L foot normal (EHR); 10g monofilament sensation R foot normal (EHR); All pulses present in left foot (EHR); All pulses present in left lower limb (EHR); All pulses present in right foot (EHR); All pulses present in right lower l | I2: Proliferative retinopathy due to diabetes mellitus (day -458); Severe nonproliferative retinopathy due to diabetes mellitus (day -2234) | J2: insulin isophane (day -2864, for 55 days); insulin, regular, human (day -2864, for 55 days); insulin, regular, human (day -2775, for 149 days); insulin isophane (day -2775, for 149 days); insulin, regular, human (day -2568, for 55 days); insulin isophane | M2: HbA1c measurement (DCCT aligned) (82 millimole per mole, day 0); | O2: Nonproliferative retinopathy of left eye due to diabetes mellitus (day 818, 1161); Nonproliferative retinopathy of right eye due to diabetes mellitus (day 182, 818); Preproliferative retinopathy of left eye due to diabetes mellitus (day 1651); Proliferati | Q2: insulin isophane (day 61, for 27 days); insulin, regular, human (day 61, for 55 days); insulin isophane (day 151, for 27 days); insulin, regular, human (day 151, for 55 days); insulin isophane (day 221, for 69 days); insulin, regular, human (day 263, for | S2: CASE (complications + treatment) | T2: Likely index date misclassification (complications before index)
A3: 2352010389 | B3: 20 | C3: Male | D3: -85 days - 166 days | F3: Acquired deviated nasal septum (EHR); All pulses present in left lower limb (EHR); All pulses present in right lower limb (EHR); Blood pressure finding (EHR); Finding of foot region (EHR); Normal tactile sensation (EHR); Temporomandibular joint disorder ( | G3: Family history of diabetes mellitus (day -85) | I3: Type 1 diabetes mellitus (day -69) | M3: Glucose measurement, blood (6.4 millimole per liter, abnormal - high, day -17); HbA1c measurement (DCCT aligned) (58 millimole per mole, day -17); | Q3: insulin aspart, human (day 89, for 11 days); insulin glargine (day 89, for 27 days); | S3: CASE (complications + treatment) | T3: Likely index date misclassification (t1dm diagnosis before index?)
A4: 244010017 | B4: 17 | C4: Female | D4: -2281 days - 4538 days | F4: Acute upper respiratory infection (EHR); Acute upper respiratory infection (EHR); Type 1 diabetes mellitus (EHR); Type 1 diabetes mellitus (EHR); | I4: Type 1 diabetes mellitus (day -38) | J4: insulin, regular, human (day -32, for 408 days); insulin lispro (day -32, for 27 days); insulin isophane (day -32, for 408 days); | O4: Ketoacidotic coma due to type 1 diabetes mellitus (day 1871); Type 1 diabetes mellitus (day 66) | Q4: insulin lispro (day 125, for 27 days); insulin, regular, human (day 413, for 107 days); insulin isophane (day 413, for 107 days); insulin lispro (day 447, for 27 days); insulin isophane (day 583, for 27 days); insulin, regular, human (day 583, for 27 days | S4: CASE (complications + treatment) | T4: Likely index date misclassification (t1dm diagnosis before index?)
A5: 5359010662 | B5: 51 | C5: Male | D5: -2 days - 854 days | E5: Office Visit | F5: Alcohol dependence (EHR); Alcoholic cirrhosis (EHR); Asthma (EHR); Epilepsy (EHR); Glaucoma (EHR); Retinal detachment (EHR); Traumatic or nontraumatic brain injury (EHR); Type 1 diabetes mellitus (EHR); | M5: HbA1c measurement (DCCT aligned) (84 millimole per mole, abnormal - high, day 14); | Q5: insulin isophane (day 0, for 627 days); insulin, regular, human (day 0, for 627 days); insulin, regular, human (day 742, for 0 days); insulin isophane (day 742, for 0 days); insulin detemir (day 742, for 0 days); insulin, regular, human (day 783, for 0 da | S5: PROBABLE (treatment only)
A6: 261610479 | B6: 39 | C6: Female | D6: -4686 days - 3219 days | F6: All pulses present in left lower limb (EHR); All pulses present in right lower limb (EHR); Blood pressure finding (EHR); Type 1 diabetes mellitus (EHR); | G6: Diabetes mellitus (day -4670, -4635, -4228, -4130, -3731, -2970, -1745, -576, -499, -430, -317) | I6: Type 1 diabetes mellitus (day -476) | J6: insulin isophane (day -4565, for 3234 days); insulin, regular, human (day -4565, for 77 days); insulin, regular, human (day -4419, for 393 days); insulin, regular, human (day -3965, for 29 days); insulin, regular, human (day -3878, for 2350 days); metform | M6: HbA1c measurement (DCCT aligned) (7.7 percent, day 0); | Q6: insulin aspart, human (day 53, for 30 days); insulin aspart, human (day 115, for 0 days); insulin aspart, human (day 151, for 0 days); insulin aspart, human (day 196, for 0 days); insulin aspart, human (day 245, for 0 days); insulin aspart, human (day 276 | S6: PROBABLE (treatment only) | T6: Likely index date misclassification (t1dm diagnosis before index?). Some records of metformin, indicated for type 2 dm
A7: 378410775 | B7: 34 | C7: Male | D7: -274 days - 8161 days | F7: All pulses present in left lower limb (EHR); All pulses present in right lower limb (EHR); Type 1 diabetes mellitus (EHR); | G7: Essential hypertension (day -69) | I7: Type 1 diabetes mellitus (day -48) | J7: insulin, regular, human (day -207, for 291 days); insulin isophane (day -207, for 291 days); | M7: HbA1c measurement (DCCT aligned) (0 , day -28); HbA1c measurement (DCCT aligned) (7.8 , day -28); | N7: Essential hypertension (day -69) | O7: Disorder of left macula due to diabetes mellitus (day 3108, 7617, 7703); Disorder of right macula due to diabetes mellitus (day 7617, 7703); Nonproliferative retinopathy due to diabetes mellitus (day 371); Nonproliferative retinopathy of left eye due to d | Q7: insulin, regular, human (day 115, for 146 days); insulin isophane (day 115, for 146 days); insulin isophane (day 296, for 53 days); insulin, regular, human (day 296, for 53 days); insulin, regular, human (day 382, for 368 days); insulin isophane (day 382, | S7: CASE (complications + treatment) | T7: Likely index date misclassification (t1dm diagnosis before index?)
A8: 1502010397 | B8: 16 | C8: Male | D8: -2646 days - 911 days | F8: All pulses present in left lower limb (EHR); All pulses present in right lower limb (EHR); Blood pressure finding (EHR); Type 1 diabetes mellitus (EHR); | I8: Type 1 diabetes mellitus (day -677, -630) | J8: insulin aspart, human (day -676, for 1586 days); insulin isophane (day -676, for 44 days); insulin, regular, human (day -676, for 44 days); insulin aspart protamine, human (day -645, for 1150 days); insulin detemir (day -104, for 23 days); insulin detemir | Q8: insulin detemir (day 55, for 30 days); insulin detemir (day 140, for 0 days); insulin detemir (day 232, for 0 days); insulin detemir (day 315, for 30 days); insulin glargine (day 414, for 28 days); metformin (day 414, for 29 days); metformin (day 478, for | S8: PROBABLE (treatment only) | T8: Likely index date misclassification (t1dm diagnosis before index?). Some records of metformin, indicated for type 2 dm
A9: 2353710622 | B9: 18 | C9: Female | D9: -2093 days - 237 days | F9: All pulses present in left lower limb (EHR); All pulses present in right lower limb (EHR); Blood pressure finding (EHR); Type 1 diabetes mellitus (EHR); | G9: Candidiasis (day -160) | I9: Type 1 diabetes mellitus (day -435) | J9: insulin glargine (day -435, for 13 days); insulin aspart, human (day -435, for 13 days); insulin glargine (day -380, for 23 days); insulin aspart, human (day -380, for 86 days); insulin glargine (day -294, for 0 days); insulin aspart, human (day -247, for | M9: HbA1c measurement (DCCT aligned) (86 millimole per mole, day -7); | Q9: insulin aspart, human (day 34, for 0 days); insulin degludec (day 34, for 0 days); insulin aspart, human (day 78, for 0 days); insulin aspart, human (day 126, for 0 days); insulin degludec (day 126, for 0 days); insulin degludec (day 202, for 0 days); ins | S9: PROBABLE (treatment only) | T9: Likely index date misclassification (t1dm diagnosis before index?)
A10: 1045410614 | B10: 40 | C10: Female | D10: -14 days - 5874 days | E10: Office Visit | F10: Allergic reaction to drug (EHR); Type 1 diabetes mellitus (EHR); | O10: Disorder of nervous system due to diabetes mellitus (day 3240, 5340) | Q10: insulin, regular, human (day 50, for 29 days); insulin isophane (day 50, for 29 days); insulin, regular, human (day 178, for 29 days); insulin isophane (day 178, for 29 days); insulin, regular, human (day 246, for 29 days); insulin isophane (day 246, for | S10: CASE (complications + treatment)
A11: 4803410866 | B11: 20 | C11: Female | D11: -12 days - 83 days | E11: Office Visit | F11: Asthma (EHR); Obesity (EHR); Type 1 diabetes mellitus (EHR); | N11: Obesity (day 0) | Q11: insulin aspart, human (day 0, for 55 days); insulin glargine (day 0, for 0 days); insulin glargine (day 70, for 0 days); | S11: PROBABLE (treatment only)
A12: 384210994 | B12: 30 | C12: Male | D12: -7106 days - 903 days | E12: Office Visit | F12: Asymptomatic periapical periodontitis (EHR); Dental caries (EHR); Type 1 diabetes mellitus (EHR); | G12: Cyst of pancreas (day -5967, -4488, -3139) | Q12: insulin glargine (day 8, for 178 days); insulin aspart, human (day 8, for 178 days); insulin aspart, human (day 218, for 243 days); insulin glargine (day 218, for 243 days); insulin aspart, human (day 543, for 28 days); insulin glargine (day 543, for 28 d | S12: PROBABLE (treatment only)
A13: 77110497 | B13: 26 | C13: Male | D13: -3834 days - 107 days | F13: Atopic conjunctivitis (EHR); Type 1 diabetes mellitus (EHR); | G13: Diabetes mellitus (day -2101, -1801, -576); Diabetic - good control (day -2085, -1779, -1289, -1107, -771) | I13: Retinopathy due to diabetes mellitus (day -341); Type 1 diabetes mellitus (day -2008, -1304) | J13: insulin, regular, human (day -2095, for 35 days); insulin isophane (day -2095, for 35 days); insulin, regular, human (day -2024, for 29 days); insulin isophane (day -2024, for 29 days); insulin, regular, human (day -1954, for 29 days); insulin isophane (d | S13: CASE (complications + treatment) | T13: Likely index date misclassification (complications before index)
A14: 35210409 | B14: 29 | C14: Male | D14: -2078 days - 851 days | F14: Blood pressure finding (EHR); Type 1 diabetes mellitus (EHR); | G14: Diabetes mellitus (day -1829, -1186, -286) | I14: Type 1 diabetes mellitus (day -972) | J14: insulin, regular, human (day -2052, for 98 days); insulin isophane (day -1996, for 42 days); insulin isophane (day -1878, for 632 days); insulin, regular, human (day -1878, for 156 days); insulin lispro (day -1707, for 353 days); insulin lispro (day -1323 | O14: Type 1 diabetes mellitus (day 624, 704) | Q14: insulin lispro (day 25, for 27 days); insulin lispro (day 104, for 67 days); insulin glargine (day 180, for 57 days); insulin lispro (day 210, for 27 days); insulin glargine (day 277, for 154 days); insulin lispro (day 343, for 27 days); insulin lispro (d | S14: PROBABLE (treatment only) | T14: Likely index date misclassification (t1dm diagnosis before index?)
A15: 153910595 | B15: 62 | C15: Male | D15: -1716 days - 479 days | F15: Blood pressure finding (EHR); Finding of vibration sense (EHR); Pulse present in left dorsalis pedis artery (EHR); Pulse present in left posterior tibial artery (EHR); Pulse present in right dorsalis pedis artery (EHR); Pulse present in right posterior ti | G15: Diabetes mellitus (day -778, -455, -372); Essential hypertension (day -1008); Insulin treated type 2 diabetes mellitus (day -778); Type 2 diabetes mellitus (day -372) | I15: Type 1 diabetes mellitus (day -778) | J15: insulin isophane (day -35, for 312 days); | M15: Glucose measurement, blood (14.8 , day -9); HbA1c measurement (DCCT aligned) (5.8 , day -9); Glucose measurement, blood (14.8 , day 0); HbA1c measurement (DCCT aligned) (5.8 , day 0); Urine screening for glucose (day 0); | O15: Type 1 diabetes mellitus (day 228) | Q15: insulin isophane (day 322, for 144 days); | S15: NON-CASE (T2DM records) | T15: Likely index date misclassification (t2dm diagnosis before index?)
A16: 274210173 | B16: 77 | C16: Female | D16: -357 days - 765 days | F16: Blood pressure finding (EHR); Type 1 diabetes mellitus (EHR); | G16: Diabetes mellitus (day -91) | I16: Type 1 diabetes mellitus (day -91) | J16: insulin, regular, human (day -91, for 163 days); insulin isophane (day -91, for 163 days); | Q16: insulin isophane (day 164, for 44 days); insulin, regular, human (day 164, for 44 days); insulin isophane (day 282, for 27 days); insulin, regular, human (day 282, for 27 days); insulin isophane (day 357, for 27 days); insulin, regular, human (day 357, fo | S16: PROBABLE (treatment only) | T16: Likely index date misclassification (t1dm diagnosis before index?)
A17: 436610288 | B17: 67 | C17: Female | D17: -5268 days - 480 days | F17: Blood pressure finding (EHR); Type 1 diabetes mellitus (EHR); | G17: Diabetes mellitus (day -4682, -4472, -4000, -3916, -2986); Family history of diabetes mellitus (day -3923); Type 2 diabetes mellitus (day -5140, -4197, -4063, -3309, -2993) | I17: Autonomic neuropathy due to diabetes mellitus (day -3779); Disorder of nervous system due to diabetes mellitus (day -3552, -3281, -3090); Neuropathy due to diabetes mellitus (day -4609); Type 1 diabetes mellitus (day -2979, -88) | J17: metformin (day -5250, for 1522 days); insulin isophane (day -5241, for 2196 days); acarbose (day -5236, for 1728 days); pioglitazone (day -4000, for 27 days); pioglitazone (day -3916, for 184 days); insulin glargine (day -3902, for 37 days); metformin (da | M17: HbA1c measurement (DCCT aligned) (34 millimole per mole, normal, day -7); | Q17: insulin isophane (day 323, for 27 days); insulin isophane (day 385, for 112 days); | S17: NON-CASE (T2DM records) | T17: Likely index date misclassification (t2dm diagnosis and complications before index?)
A18: 503810366 | B18: 72 | C18: Male | D18: -5496 days - 1202 days | E18: Office Visit | F18: Blood pressure finding (EHR); Diabetes mellitus (EHR); Type 1 diabetes mellitus (EHR); | G18: Acute pancreatitis (day -38); Essential hypertension (day -1177, -830, -674) | N18: Acute pancreatitis (day -38); Diabetes mellitus (day 0) | Q18: insulin aspart, human (day 33, for 60 days); insulin aspart protamine, human (day 33, for 60 days); insulin glargine (day 125, for 98 days); insulin glargine (day 279, for 27 days); insulin glargine (day 369, for 67 days); insulin glargine (day 510, for 2 | S18: PROBABLE (treatment only) | T18: Maybe secondary diabetes (differential) as presentation coincides with acute pancreatitis
A19: 559910689 | B19: 34 | C19: Male | D19: -1186 days - 4197 days | E19: Office Visit->Office Visit | F19: Blood pressure finding (EHR); Type 1 diabetes mellitus (EHR); | G19: Diabetes mellitus (day -350) | J19: insulin, regular, human (day -1108, for 27 days); insulin, regular, human (day -1043, for 27 days); insulin, regular, human (day -892, for 85 days); insulin, regular, human (day -599, for 27 days); insulin, regular, human (day -487, for 27 days); insulin, | M19: HbA1c measurement (DCCT aligned) (8.4 , day 0); | O19: Diabetic hand syndrome (day 882, 958); Nonproliferative retinopathy due to diabetes mellitus (day 376); Retinopathy due to diabetes mellitus (day 3657, 4043); Type 1 diabetes mellitus (day 950, 1137) | Q19: insulin, regular, human (day 21, for 27 days); insulin, regular, human (day 112, for 27 days); insulin, regular, human (day 207, for 27 days); insulin, regular, human (day 341, for 27 days); insulin, regular, human (day 416, for 27 days); insulin, regular | S19: CASE (complications + treatment) | T19: Likely index date misclassification (insulin treatment before index)
A20: 644210241 | B20: 66 | C20: Male | D20: -4926 days - 262 days | E20: Office Visit | F20: Blood pressure finding (EHR); Type 1 diabetes mellitus (EHR); | G20: Diabetes mellitus (day -2589, -469); Essential hypertension (day -155); Type 2 diabetes mellitus (day -2589) | I20: Nonproliferative retinopathy due to diabetes mellitus (day -173) | J20: glyburide (day -1513, for 111 days); | Q20: insulin isophane (day 0, for 27 days); insulin, regular, human (day 0, for 27 days); insulin isophane (day 80, for 27 days); insulin, regular, human (day 80, for 27 days); insulin isophane (day 142, for 27 days); insulin, regular, human (day 142, for 27 d | S20: NON-CASE (T2DM records) | T20: Likely index date misclassification (t2dm diagnosis before index?)
A21: 812210207 | B21: 38 | C21: Female | D21: -85 days - 4750 days | E21: Office Visit | F21: Blood pressure finding (EHR); Type 1 diabetes mellitus (EHR); | M21: Serum fasting glucose measurement (15 millimole per liter, day 12); | Q21: insulin isophane (day 0, for 76 days); insulin, regular, human (day 0, for 76 days); insulin, regular, human (day 113, for 133 days); insulin isophane (day 113, for 133 days); insulin, regular, human (day 289, for 27 days); insulin isophane (day 289, for | S21: PROBABLE (treatment only)
A22: 925810409 | B22: 31 | C22: Female | D22: -2831 days - 1990 days | F22: Blood pressure finding (EHR); Blood pressure finding (EHR); Blood pressure finding (EHR); Blood pressure finding (EHR); Blood pressure finding (EHR); Blood pressure finding (EHR); Blood pressure finding (EHR); Type 1 diabetes mellitus (EHR); Type 1 diabet | G22: Candidiasis (day -2698, -2159); Candidiasis of vagina (day -2699); Diabetes mellitus (day -1851, -1669, -1368, -1168) | I22: Retinopathy due to diabetes mellitus (day -2272, -1424, -866, -140); Type 1 diabetes mellitus (day -853, -140, -28) | J22: insulin isophane (day -2791, for 230 days); insulin, regular, human (day -2791, for 230 days); insulin isophane (day -2527, for 142 days); insulin, regular, human (day -2527, for 142 days); insulin, regular, human (day -2337, for 54 days); insulin isophan | M22: HbA1c measurement (DCCT aligned) (8.3 percent, day 14); Glucose measurement, blood (9.2 millimole per liter, day 14); HbA1c measurement (DCCT aligned) (8.8 percent, day 28); | O22: Retinopathy due to diabetes mellitus (day 794, 849, 1682, 1745); Type 1 diabetes mellitus (day 80, 303, 337, 458, 591, 819, 917, 962, 997, 1193, 1234) | Q22: insulin aspart, human (day 17, for 27 days); insulin glargine (day 211, for 27 days); insulin aspart, human (day 211, for 27 days); insulin aspart, human (day 309, for 27 days); insulin glargine (day 309, for 27 days); insulin glargine (day 367, for 425 d | S22: CASE (complications + treatment) | T22: Likely index date misclassification (complications before index)
A23: 1054010302 | B23: 33 | C23: Female | D23: -4416 days - 710 days | F23: Blood pressure finding (EHR); Blood pressure finding (EHR); Blood pressure finding (EHR); Blood pressure finding (EHR); Type 1 diabetes mellitus (EHR); Type 1 diabetes mellitus (EHR); Type 1 diabetes mellitus (EHR); Type 1 diabetes mellitus (EHR); | G23: Candidiasis (day -3653, -3374, -2751, -2520, -2473, -1795, -1539, -1274, -1177, -335); Candidiasis of vagina (day -3047, -2179, -2123, -1896); Diabetes mellitus (day -4042, -3471, -3110, -2960, -2737, -2544, -2330, -2270, -2226, -2192, -2044, -1974, -1647 | I23: Hypoglycemic coma due to type 1 diabetes mellitus (day -2197, -2158); Ketoacidosis due to type 1 diabetes mellitus (day -3038); Loss of hypoglycemic warning due to diabetes mellitus (day -836, -581); Proliferative retinopathy due to diabetes mellitus (day | J23: insulin lispro (day -4396, for 29 days); insulin lispro (day -4336, for 29 days); insulin isophane (day -4336, for 29 days); insulin lispro (day -4251, for 29 days); insulin isophane (day -4251, for 29 days); insulin lispro (day -4129, for 29 days); insul | M23: Serum fasting glucose measurement (3.4 millimole per liter, normal, day 0); HbA1c measurement (DCCT aligned) (83 millimole per mole, abnormal - high, day 0); | O23: Proliferative retinopathy due to diabetes mellitus (day 639); Type 1 diabetes mellitus (day 40) | Q23: insulin lispro (day 77, for 0 days); insulin detemir (day 77, for 74 days); insulin lispro (day 124, for 0 days); insulin detemir (day 182, for 179 days); insulin lispro (day 182, for 0 days); insulin lispro (day 238, for 0 days); insulin lispro (day 295, | S23: CASE (complications + treatment) | T23: Likely index date misclassification (complications before index)
A24: 1525510677 | B24: 39 | C24: Male | D24: -2640 days - 6782 days | F24: Blood pressure finding (EHR); Blood pressure finding (EHR); Blood pressure finding (EHR); Blood pressure finding (EHR); Type 1 diabetes mellitus (EHR); Type 1 diabetes mellitus (EHR); Type 1 diabetes mellitus (EHR); Type 1 diabetes mellitus (EHR); | G24: Diabetes mellitus (day -980) | I24: Type 1 diabetes mellitus (day -1184, -939) | J24: insulin aspart protamine, human (day -966, for 152 days); insulin aspart, human (day -966, for 152 days); insulin aspart, human (day -771, for 0 days); insulin aspart protamine, human (day -771, for 0 days); insulin aspart protamine, human (day -715, for | M24: Self-monitoring of blood glucose (day 0); Glucose measurement, blood (11.5 , day 0); | O24: Disorder of left macula due to diabetes mellitus (day 5412); Disorder of macula due to diabetes mellitus (day 5340, 5412); Nonproliferative retinopathy due to diabetes mellitus (day 3952, 4402, 5340, 5412, 5643); Nonproliferative retinopathy of left eye d | Q24: insulin aspart protamine, human (day 5, for 0 days); insulin aspart, human (day 5, for 0 days); insulin aspart protamine, human (day 46, for 0 days); insulin aspart, human (day 46, for 0 days); insulin aspart protamine, human (day 110, for 0 days); insuli | S24: CASE (complications + treatment) | T24: Likely index date misclassification (complications before index)
A25: 1721910803 | B25: 34 | C25: Male | D25: days - days | E25: Office Visit->Office Visit | F25: Blood pressure finding (EHR); Blood pressure finding (EHR); Type 1 diabetes mellitus (EHR); Type 1 diabetes mellitus (EHR); | Q25: insulin detemir (day 10, for 1158 days); insulin aspart, human (day 10, for 2252 days); insulin degludec (day 1164, for 72 days); insulin degludec (day 1270, for 0 days); insulin degludec (day 1316, for 319 days); insulin degludec (day 1667, for 164 days) | S25: PROBABLE (treatment only)
A26: 1985010365 | B26: 72 | C26: Male | D26: -300 days - 1502 days | E26: Office Visit->Office Visit | F26: Blood pressure finding (EHR); Type 1 diabetes mellitus (EHR); | J26: insulin isophane (day -289, for 142 days); insulin, regular, human (day -287, for 0 days); insulin, regular, human (day -217, for 172 days); insulin isophane (day -72, for 29 days); insulin, regular, human (day -12, for 191 days); insulin isophane (day -1 | M26: Glucose measurement, blood (12.7 millimole per liter, day -12); | O26: Persistent microalbuminuria due to type 1 diabetes mellitus (day 1080); Type 1 diabetes mellitus (day 48, 517, 595) | Q26: insulin isophane (day 96, for 29 days); insulin, regular, human (day 211, for 82 days); insulin isophane (day 211, for 29 days); insulin, regular, human (day 327, for 792 days); insulin isophane (day 327, for 29 days); insulin isophane (day 418, for 101 d | S26: PROBABLE (treatment only)
A27: 2020510974 | B27: 55 | C27: Male | D27: -3204 days - 4530 days | E27: Office Visit->Office Visit | F27: Blood pressure finding (EHR); Type 1 diabetes mellitus (EHR); | G27: Essential hypertension (day -3113); Hyperlipidemia (day -2840, -2667, -2030, -1952, -1862, -1077, -894, -230); Insulin treated type 2 diabetes mellitus (day -3204); Obesity (day -2484); Type 2 diabetes mellitus (day -3204, -2675, -2303, -2041, -824, -467) | I27: Nonproliferative retinopathy due to diabetes mellitus (day -3070); Retinopathy due to diabetes mellitus (day -2484) | J27: metformin (day -3178, for 56 days); insulin, regular, human (day -3143, for 206 days); insulin isophane (day -3143, for 206 days); metformin (day -3086, for 104 days); metformin (day -2945, for 89 days); insulin aspart, human (day -2939, for 4424 days); i | O27: Type 1 diabetes mellitus (day 1198) | Q27: metformin (day 115, for 54 days); metformin (day 205, for 138 days); metformin (day 391, for 371 days); metformin (day 822, for 116 days); metformin (day 981, for 57 days); metformin (day 1127, for 27 days); metformin (day 1198, for 27 days); metformin (d | S27: NON-CASE (T2DM records) | T27: Likely index date misclassification (t2dm diagnosis and metformin treatment before index?)
A28: 2520610627 | B28: 44 | C28: Female | D28: days - days | E28: Office Visit->Office Visit | F28: Blood pressure finding (EHR); Type 1 diabetes mellitus (EHR); | O28: Retinopathy due to diabetes mellitus (day 188); Type 1 diabetes mellitus (day 539) | Q28: insulin aspart, human (day 82, for 0 days); insulin detemir (day 82, for 84 days); insulin aspart, human (day 367, for 44 days); insulin aspart, human (day 454, for 27 days); insulin detemir (day 454, for 27 days); insulin detemir (day 553, for 122 days); | S28: CASE (complications + treatment)
A29: 3954810544 | B29: 58 | C29: Male | D29: -2017 days - 3651 days | F29: Blood pressure finding (EHR); Finding of foot region (EHR); Type 1 diabetes mellitus (EHR); | G29: Calculus of pancreas (day -1068); Diabetes mellitus (day -581); Type 2 diabetes mellitus (day -1919, -581) | I29: Type 1 diabetes mellitus (day -581) | J29: glipizide (day -1596, for 124 days); glipizide (day -1410, for 27 days); glipizide (day -1305, for 96 days); glipizide (day -1165, for 55 days); glipizide (day -1065, for 55 days); insulin isophane (day -1023, for 27 days); insulin, regular, human (day -9 | M29: HbA1c measurement (DCCT aligned) (7.3 percent, day 0); | O29: Nonproliferative retinopathy due to diabetes mellitus (day 2692); Preproliferative retinopathy due to diabetes mellitus (day 3024); Retinopathy due to type 2 diabetes mellitus (day 2446) | Q29: insulin isophane (day 39, for 27 days); insulin lispro (day 39, for 27 days); insulin isophane (day 472, for 132 days); insulin lispro (day 528, for 76 days); insulin lispro (day 781, for 27 days); insulin isophane (day 781, for 27 days); insulin glargine | S29: NON-CASE (T2DM records) | T29: Likely index date misclassification (t2dm diagnosis and metformin treatment before index?)
A30: 726710461 | B30: 47 | C30: Male | D30: -1428 days - 6734 days | E30: Office Visit->Office Visit | F30: Diabetes mellitus (EHR); Diabetes mellitus (EHR); Type 1 diabetes mellitus (EHR); Type 1 diabetes mellitus (EHR); | G30: Diabetes mellitus (day -1047) | J30: insulin, protamine zinc, beef (day -1422, for 27 days); insulin, protamine zinc, beef (day -1348, for 27 days); insulin, protamine zinc, beef (day -1264, for 27 days); insulin, protamine zinc, beef (day -1198, for 27 days); insulin, protamine zinc, beef ( | N30: Diabetes mellitus (day 0); Retinopathy due to diabetes mellitus (day 76) | O30: Proliferative retinopathy due to diabetes mellitus (day 3989, 4187, 4898); Retinopathy due to diabetes mellitus (day 76); Type 1 diabetes mellitus (day 3836, 3995, 4195, 4797, 5033, 5098, 5546) | Q30: insulin, regular, human (day 315, for 460 days); insulin, regular, human (day 838, for 630 days); insulin, regular, human (day 1504, for 27 days); insulin isophane (day 1567, for 1167 days); insulin, regular, human (day 1567, for 1141 days); insulin, regu | S30: CASE (complications + treatment) | T30: Likely index date misclassification (insulin treatment before index)
A31: 833410289 | B31: 24 | C31: Female | D31: -2491 days - 4727 days | E31: Office Visit->Office Visit | F31: Diabetes mellitus (EHR); Type 1 diabetes mellitus (EHR); | N31: Diabetes mellitus (day 0); Type 2 diabetes mellitus (day 1) | O31: Diabetic ketoacidosis (day 2350, 2965, 3454, 3982); Retinopathy due to diabetes mellitus (day 3925); Type 1 diabetes mellitus (day 1627, 3035) | Q31: metformin (day 3, for 29 days); metformin (day 72, for 29 days); metformin (day 302, for 29 days); metformin (day 423, for 29 days); insulin, regular, human (day 436, for 27 days); insulin isophane (day 436, for 27 days); insulin isophane (day 519, for 27 | S31: CASE (complications + treatment)
A32: 971510284 | B32: 60 | C32: Male | D32: -350 days - 4511 days | E32: Office Visit->Office Visit | F32: Diabetes mellitus (EHR); Type 1 diabetes mellitus (EHR); | N32: Diabetes mellitus (day 0) | O32: Neuropathy due to diabetes mellitus (day 2914) | Q32: insulin, regular, human (day 989, for 27 days); insulin isophane (day 989, for 27 days); insulin isophane (day 1150, for 27 days); insulin, regular, human (day 1150, for 27 days); insulin isophane (day 1239, for 27 days); insulin, regular, human (day 1239 | S32: CASE (complications + treatment)
A33: 1094310233 | B33: 4 | C33: Male | D33: -1374 days - 6593 days | E33: Office Visit->Office Visit | F33: Diabetes mellitus (EHR); Type 1 diabetes mellitus (EHR); | M33: Urine screening for glucose (day 0); | N33: Diabetes mellitus (day 0) | O33: Type 1 diabetes mellitus (day 4064) | Q33: insulin, regular, human (day 4, for 541 days); insulin isophane (day 4, for 541 days); insulin isophane (day 710, for 27 days); insulin, regular, human (day 710, for 27 days); insulin isophane (day 770, for 118 days); insulin, regular, human (day 770, for | S33: PROBABLE (treatment only) | T33: Very young (4yo). We could say that new diabetes at this age is almost warrantee that this is a t1dm CASE
A34: 38410333 | B34: 33 | C34: Female | D34: -157 days - 4631 days | E34: Office Visit->Office Visit | F34: Hyperlipidemia (EHR); Neuropathic arthropathy due to diabetes mellitus (EHR); Neuropathy due to diabetes mellitus (EHR); Retinopathy due to diabetes mellitus (EHR); Type 1 diabetes mellitus (EHR); | J34: insulin isophane (day -153, for 398 days); insulin lispro (day -153, for 230 days); | N34: Hyperlipidemia (day 0); Neuropathic arthropathy due to diabetes mellitus (day 0); Neuropathy due to diabetes mellitus (day 0); Retinopathy due to diabetes mellitus (day 0) | O34: Mixed diabetic ulcer - foot (day 3620); Neuropathic arthropathy due to diabetes mellitus (day 320); Retinopathy due to diabetes mellitus (day 327); Type 1 diabetes mellitus (day 722) | Q34: metformin (day 112, for 3000 days); insulin lispro (day 126, for 119 days); insulin lispro (day 293, for 186 days); insulin isophane (day 340, for 139 days); insulin lispro (day 529, for 121 days); insulin glargine (day 529, for 121 days); insulin lispro | S34: CASE (complications + treatment) | T34: Likely index date misclassification (insulin before index)
A35: 3525210465 | B35: 56 | C35: Male | D35: -3534 days - 923 days | F35: Pain of knee region (EHR); Type 1 diabetes mellitus (EHR); | I35: Type 1 diabetes mellitus (day -1266) | J35: insulin, regular, human (day -1266, for 69 days); insulin isophane (day -1266, for 69 days); insulin isophane (day -883, for 27 days); insulin, regular, human (day -883, for 27 days); insulin isophane (day -758, for 27 days); insulin, regular, human (day | Q35: insulin, regular, human (day 103, for 27 days); insulin isophane (day 103, for 27 days); insulin, regular, human (day 187, for 27 days); insulin isophane (day 187, for 27 days); insulin isophane (day 264, for 57 days); insulin, regular, human (day 264, fo | S35: PROBABLE (treatment only)
A36: 2010394 | B36: 33 | C36: Male | D36: -1662 days - 3112 days | E36: Office Visit->Office Visit | F36: Type 1 diabetes mellitus (EHR); Type 1 diabetes mellitus (EHR); | J36: insulin isophane (day -1654, for 27 days); insulin, regular, human (day -1654, for 27 days); insulin, regular, human (day -1581, for 161 days); insulin isophane (day -1581, for 163 days); insulin isophane (day -1366, for 84 days); insulin, regular, human | O36: Disorder of eye due to type 1 diabetes mellitus (day 1141); Type 1 diabetes mellitus (day 105) | Q36: insulin isophane (day 78, for 88 days); insulin, regular, human (day 78, for 88 days); insulin, regular, human (day 212, for 27 days); insulin isophane (day 212, for 27 days); insulin, regular, human (day 279, for 257 days); insulin isophane (day 279, for | S36: CASE (complications + treatment) | T36: Likely index date misclassification (insulin before index)
A37: 62910668 | B37: 59 | C37: Male | D37: -3237 days - 2951 days | E37: Office Visit->Office Visit | F37: Type 1 diabetes mellitus (EHR); | G37: Essential hypertension (day -2509) | M37: HbA1c measurement (DCCT aligned) (11 percent, day 0); HbA1c measurement (DCCT aligned) (97 millimole per mole, day 0); | O37: Type 1 diabetes mellitus (day 392, 803) | Q37: insulin glargine (day 66, for 27 days); insulin aspart, human (day 66, for 27 days); insulin aspart, human (day 158, for 0 days); insulin glargine (day 180, for 0 days); insulin aspart, human (day 223, for 0 days); insulin aspart, human (day 279, for 0 da | S37: PROBABLE (treatment only)
A38: 75310568 | B38: 54 | C38: Female | D38: -871 days - 493 days | E38: Office Visit | F38: Type 1 diabetes mellitus (EHR); | G38: Diabetes mellitus (day -222) | I38: Skin ulcer due to diabetes mellitus (day -222) | J38: metformin (day -639, for 439 days); insulin, regular, human (day -220, for 182 days); | M38: HbA1c measurement (DCCT aligned) (0 , day 27); | Q38: metformin (day 2, for 68 days); insulin, regular, human (day 8, for 126 days); metformin (day 111, for 27 days); insulin, regular, human (day 219, for 274 days); insulin isophane (day 250, for 27 days); insulin isophane (day 393, for 27 days); | S38: NON-CASE (T2DM treatment, metformin) | T38: Likely index date misclassification (complications before index)
A39: 120310166 | B39: 33 | C39: Female | D39: -5336 days - 3561 days | E39: Office Visit | F39: Type 1 diabetes mellitus (EHR); | G39: Diabetes mellitus (day -3540); Family history of diabetes mellitus (day -3214, -1877) | I39: Disorder of right macula due to diabetes mellitus (day -484); Nonproliferative retinopathy due to diabetes mellitus (day -2041); Nonproliferative retinopathy of left eye due to diabetes mellitus (day -484); Nonproliferative retinopathy of right eye due to | J39: insulin, regular, human (day -5335, for 122 days); insulin isophane (day -5333, for 95 days); insulin lispro (day -5214, for 1975 days); insulin isophane (day -5185, for 1666 days); insulin glargine (day -3540, for 299 days); insulin lispro (day -3106, fo | N39: Disorder of right macula due to diabetes mellitus (day 20); Nonproliferative retinopathy of left eye due to diabetes mellitus (day 20); Nonproliferative retinopathy of right eye due to diabetes mellitus (day 20) | O39: Disorder of right macula due to diabetes mellitus (day 20); Nonproliferative retinopathy of left eye due to diabetes mellitus (day 20, 601, 975, 1507, 1885, 2947, 3437); Nonproliferative retinopathy of right eye due to diabetes mellitus (day 20, 975, 1507 | Q39: insulin lispro (day 38, for 4 days); insulin lispro (day 94, for 4 days); insulin detemir (day 94, for 0 days); insulin detemir (day 146, for 0 days); insulin lispro (day 146, for 4 days); insulin lispro (day 225, for 27 days); insulin detemir (day 248, f | S39: CASE (complications + treatment) | T39: Likely index date misclassification (complications before index)
A40: 319810053 | B40: 13 | C40: Male | D40: -1520 days - 2785 days | E40: Office Visit->Office Visit | F40: Type 1 diabetes mellitus (EHR); Type 1 diabetes mellitus (EHR); | M40: Glucose measurement, blood (31.1 millimole per liter, abnormal - high, day 0); Urine screening for glucose (day 0); HbA1c measurement (DCCT aligned) (10.1 international unit per liter, abnormal - high, day 3); | O40: Diabetic ketoacidosis (day 2134); Type 1 diabetes mellitus (day 1666) | Q40: insulin isophane (day 4, for 628 days); insulin, regular, human (day 4, for 628 days); insulin isophane (day 665, for 583 days); insulin, regular, human (day 665, for 583 days); insulin aspart, human (day 1159, for 61 days); insulin glargine (day 1159, fo | S40: CASE (complications + treatment)
...

Sheet GPT 5o
A1: Adjudication (Choose One from Drop Down) | B1: personId | C1: age | D1: gender | E1: observationPeriod | F1: visitContext | G1: presentation (day 0) | H1: comorbidities (day 0) | I1: symptoms (day 0) | J1: priorDisease (before day 0) | K1: priorDrugs (before day 0) | L1: priorTreatmentProcedures (before day 0) | M1: diagnosticProcedures (before and after day 0) | N1: measurements (before and after day 0) | O1: alternativeDiagnosis (after day 0) | P1: afterDisease (after day 0) | Q1: afterTreatmentProcedures (after day 0) | R1: afterDrugs (after day 0) | S1: death | T1: ClinicalLabel
B2: 7810823 | C2: 53 | D2: Female | E2: -2979 days - 4196 days | F2: Office Visit->Office Visit | G2: 10g monofilament sensation L foot normal (EHR); 10g monofilament sensation R foot normal (EHR); All pulses present in left foot (EHR); All pulses present in left lower limb (EHR); All pulses present in right foot (EHR); All pulses present in right lower l | J2: Proliferative retinopathy due to diabetes mellitus (day -458); Severe nonproliferative retinopathy due to diabetes mellitus (day -2234) | K2: insulin isophane (day -2864, for 55 days); insulin, regular, human (day -2864, for 55 days); insulin, regular, human (day -2775, for 149 days); insulin isophane (day -2775, for 149 days); insulin, regular, human (day -2568, for 55 days); insulin isophane | N2: HbA1c measurement (DCCT aligned) (82 millimole per mole, day 0); | P2: Nonproliferative retinopathy of left eye due to diabetes mellitus (day 818, 1161); Nonproliferative retinopathy of right eye due to diabetes mellitus (day 182, 818); Preproliferative retinopathy of left eye due to diabetes mellitus (day 1651); Proliferati | R2: insulin isophane (day 61, for 27 days); insulin, regular, human (day 61, for 55 days); insulin isophane (day 151, for 27 days); insulin, regular, human (day 151, for 55 days); insulin isophane (day 221, for 69 days); insulin, regular, human (day 263, for | T2: Probable
B3: 2352010389 | C3: 20 | D3: Male | E3: -85 days - 166 days | G3: Acquired deviated nasal septum (EHR); All pulses present in left lower limb (EHR); All pulses present in right lower limb (EHR); Blood pressure finding (EHR); Finding of foot region (EHR); Normal tactile sensation (EHR); Temporomandibular joint disorder ( | H3: Family history of diabetes mellitus (day -85) | J3: Type 1 diabetes mellitus (day -69) | N3: Glucose measurement, blood (6.4 millimole per liter, abnormal - high, day -17); HbA1c measurement (DCCT aligned) (58 millimole per mole, day -17); | R3: insulin aspart, human (day 89, for 11 days); insulin glargine (day 89, for 27 days); | T3: Probable
B4: 244010017 | C4: 17 | D4: Female | E4: -2281 days - 4538 days | G4: Acute upper respiratory infection (EHR); Acute upper respiratory infection (EHR); Type 1 diabetes mellitus (EHR); Type 1 diabetes mellitus (EHR); | J4: Type 1 diabetes mellitus (day -38) | K4: insulin, regular, human (day -32, for 408 days); insulin lispro (day -32, for 27 days); insulin isophane (day -32, for 408 days); | P4: Ketoacidotic coma due to type 1 diabetes mellitus (day 1871); Type 1 diabetes mellitus (day 66) | R4: insulin lispro (day 125, for 27 days); insulin, regular, human (day 413, for 107 days); insulin isophane (day 413, for 107 days); insulin lispro (day 447, for 27 days); insulin isophane (day 583, for 27 days); insulin, regular, human (day 583, for 27 days | T4: Probable
B5: 5359010662 | C5: 51 | D5: Male | E5: -2 days - 854 days | F5: Office Visit | G5: Alcohol dependence (EHR); Alcoholic cirrhosis (EHR); Asthma (EHR); Epilepsy (EHR); Glaucoma (EHR); Retinal detachment (EHR); Traumatic or nontraumatic brain injury (EHR); Type 1 diabetes mellitus (EHR); | N5: HbA1c measurement (DCCT aligned) (84 millimole per mole, abnormal - high, day 14); | R5: insulin isophane (day 0, for 627 days); insulin, regular, human (day 0, for 627 days); insulin, regular, human (day 742, for 0 days); insulin isophane (day 742, for 0 days); insulin detemir (day 742, for 0 days); insulin, regular, human (day 783, for 0 da | T5: Probable
B6: 261610479 | C6: 39 | D6: Female | E6: -4686 days - 3219 days | G6: All pulses present in left lower limb (EHR); All pulses present in right lower limb (EHR); Blood pressure finding (EHR); Type 1 diabetes mellitus (EHR); | H6: Diabetes mellitus (day -4670, -4635, -4228, -4130, -3731, -2970, -1745, -576, -499, -430, -317) | J6: Type 1 diabetes mellitus (day -476) | K6: insulin isophane (day -4565, for 3234 days); insulin, regular, human (day -4565, for 77 days); insulin, regular, human (day -4419, for 393 days); insulin, regular, human (day -3965, for 29 days); insulin, regular, human (day -3878, for 2350 days); metform | N6: HbA1c measurement (DCCT aligned) (7.7 percent, day 0); | R6: insulin aspart, human (day 53, for 30 days); insulin aspart, human (day 115, for 0 days); insulin aspart, human (day 151, for 0 days); insulin aspart, human (day 196, for 0 days); insulin aspart, human (day 245, for 0 days); insulin aspart, human (day 276 | T6: Probable
B7: 378410775 | C7: 34 | D7: Male | E7: -274 days - 8161 days | G7: All pulses present in left lower limb (EHR); All pulses present in right lower limb (EHR); Type 1 diabetes mellitus (EHR); | H7: Essential hypertension (day -69) | J7: Type 1 diabetes mellitus (day -48) | K7: insulin, regular, human (day -207, for 291 days); insulin isophane (day -207, for 291 days); | N7: HbA1c measurement (DCCT aligned) (0 , day -28); HbA1c measurement (DCCT aligned) (7.8 , day -28); | O7: Essential hypertension (day -69) | P7: Disorder of left macula due to diabetes mellitus (day 3108, 7617, 7703); Disorder of right macula due to diabetes mellitus (day 7617, 7703); Nonproliferative retinopathy due to diabetes mellitus (day 371); Nonproliferative retinopathy of left eye due to d | R7: insulin, regular, human (day 115, for 146 days); insulin isophane (day 115, for 146 days); insulin isophane (day 296, for 53 days); insulin, regular, human (day 296, for 53 days); insulin, regular, human (day 382, for 368 days); insulin isophane (day 382, | T7: No Case
B8: 1502010397 | C8: 16 | D8: Male | E8: -2646 days - 911 days | G8: All pulses present in left lower limb (EHR); All pulses present in right lower limb (EHR); Blood pressure finding (EHR); Type 1 diabetes mellitus (EHR); | J8: Type 1 diabetes mellitus (day -677, -630) | K8: insulin aspart, human (day -676, for 1586 days); insulin isophane (day -676, for 44 days); insulin, regular, human (day -676, for 44 days); insulin aspart protamine, human (day -645, for 1150 days); insulin detemir (day -104, for 23 days); insulin detemir | R8: insulin detemir (day 55, for 30 days); insulin detemir (day 140, for 0 days); insulin detemir (day 232, for 0 days); insulin detemir (day 315, for 30 days); insulin glargine (day 414, for 28 days); metformin (day 414, for 29 days); metformin (day 478, for | T8: Probable
B9: 2353710622 | C9: 18 | D9: Female | E9: -2093 days - 237 days | G9: All pulses present in left lower limb (EHR); All pulses present in right lower limb (EHR); Blood pressure finding (EHR); Type 1 diabetes mellitus (EHR); | H9: Candidiasis (day -160) | J9: Type 1 diabetes mellitus (day -435) | K9: insulin glargine (day -435, for 13 days); insulin aspart, human (day -435, for 13 days); insulin glargine (day -380, for 23 days); insulin aspart, human (day -380, for 86 days); insulin glargine (day -294, for 0 days); insulin aspart, human (day -247, for | N9: HbA1c measurement (DCCT aligned) (86 millimole per mole, day -7); | R9: insulin aspart, human (day 34, for 0 days); insulin degludec (day 34, for 0 days); insulin aspart, human (day 78, for 0 days); insulin aspart, human (day 126, for 0 days); insulin degludec (day 126, for 0 days); insulin degludec (day 202, for 0 days); ins | T9: Probable
B10: 1045410614 | C10: 40 | D10: Female | E10: -14 days - 5874 days | F10: Office Visit | G10: Allergic reaction to drug (EHR); Type 1 diabetes mellitus (EHR); | P10: Disorder of nervous system due to diabetes mellitus (day 3240, 5340) | R10: insulin, regular, human (day 50, for 29 days); insulin isophane (day 50, for 29 days); insulin, regular, human (day 178, for 29 days); insulin isophane (day 178, for 29 days); insulin, regular, human (day 246, for 29 days); insulin isophane (day 246, for | T10: Probable
B11: 4803410866 | C11: 20 | D11: Female | E11: -12 days - 83 days | F11: Office Visit | G11: Asthma (EHR); Obesity (EHR); Type 1 diabetes mellitus (EHR); | O11: Obesity (day 0) | R11: insulin aspart, human (day 0, for 55 days); insulin glargine (day 0, for 0 days); insulin glargine (day 70, for 0 days); | T11: No Case
B12: 384210994 | C12: 30 | D12: Male | E12: -7106 days - 903 days | F12: Office Visit | G12: Asymptomatic periapical periodontitis (EHR); Dental caries (EHR); Type 1 diabetes mellitus (EHR); | H12: Cyst of pancreas (day -5967, -4488, -3139) | R12: insulin glargine (day 8, for 178 days); insulin aspart, human (day 8, for 178 days); insulin aspart, human (day 218, for 243 days); insulin glargine (day 218, for 243 days); insulin aspart, human (day 543, for 28 days); insulin glargine (day 543, for 28 d | T12: Probable
B13: 77110497 | C13: 26 | D13: Male | E13: -3834 days - 107 days | G13: Atopic conjunctivitis (EHR); Type 1 diabetes mellitus (EHR); | H13: Diabetes mellitus (day -2101, -1801, -576); Diabetic - good control (day -2085, -1779, -1289, -1107, -771) | J13: Retinopathy due to diabetes mellitus (day -341); Type 1 diabetes mellitus (day -2008, -1304) | K13: insulin, regular, human (day -2095, for 35 days); insulin isophane (day -2095, for 35 days); insulin, regular, human (day -2024, for 29 days); insulin isophane (day -2024, for 29 days); insulin, regular, human (day -1954, for 29 days); insulin isophane (d | T13: Probable
B14: 35210409 | C14: 29 | D14: Male | E14: -2078 days - 851 days | G14: Blood pressure finding (EHR); Type 1 diabetes mellitus (EHR); | H14: Diabetes mellitus (day -1829, -1186, -286) | J14: Type 1 diabetes mellitus (day -972) | K14: insulin, regular, human (day -2052, for 98 days); insulin isophane (day -1996, for 42 days); insulin isophane (day -1878, for 632 days); insulin, regular, human (day -1878, for 156 days); insulin lispro (day -1707, for 353 days); insulin lispro (day -1323 | P14: Type 1 diabetes mellitus (day 624, 704) | R14: insulin lispro (day 25, for 27 days); insulin lispro (day 104, for 67 days); insulin glargine (day 180, for 57 days); insulin lispro (day 210, for 27 days); insulin glargine (day 277, for 154 days); insulin lispro (day 343, for 27 days); insulin lispro (d | T14: Probable
B15: 153910595 | C15: 62 | D15: Male | E15: -1716 days - 479 days | G15: Blood pressure finding (EHR); Finding of vibration sense (EHR); Pulse present in left dorsalis pedis artery (EHR); Pulse present in left posterior tibial artery (EHR); Pulse present in right dorsalis pedis artery (EHR); Pulse present in right posterior ti | H15: Diabetes mellitus (day -778, -455, -372); Essential hypertension (day -1008); Insulin treated type 2 diabetes mellitus (day -778); Type 2 diabetes mellitus (day -372) | J15: Type 1 diabetes mellitus (day -778) | K15: insulin isophane (day -35, for 312 days); | N15: Glucose measurement, blood (14.8 , day -9); HbA1c measurement (DCCT aligned) (5.8 , day -9); Glucose measurement, blood (14.8 , day 0); HbA1c measurement (DCCT aligned) (5.8 , day 0); Urine screening for glucose (day 0); | P15: Type 1 diabetes mellitus (day 228) | R15: insulin isophane (day 322, for 144 days); | T15: Probable
B16: 274210173 | C16: 77 | D16: Female | E16: -357 days - 765 days | G16: Blood pressure finding (EHR); Type 1 diabetes mellitus (EHR); | H16: Diabetes mellitus (day -91) | J16: Type 1 diabetes mellitus (day -91) | K16: insulin, regular, human (day -91, for 163 days); insulin isophane (day -91, for 163 days); | R16: insulin isophane (day 164, for 44 days); insulin, regular, human (day 164, for 44 days); insulin isophane (day 282, for 27 days); insulin, regular, human (day 282, for 27 days); insulin isophane (day 357, for 27 days); insulin, regular, human (day 357, fo | T16: Probable
B17: 436610288 | C17: 67 | D17: Female | E17: -5268 days - 480 days | G17: Blood pressure finding (EHR); Type 1 diabetes mellitus (EHR); | H17: Diabetes mellitus (day -4682, -4472, -4000, -3916, -2986); Family history of diabetes mellitus (day -3923); Type 2 diabetes mellitus (day -5140, -4197, -4063, -3309, -2993) | J17: Autonomic neuropathy due to diabetes mellitus (day -3779); Disorder of nervous system due to diabetes mellitus (day -3552, -3281, -3090); Neuropathy due to diabetes mellitus (day -4609); Type 1 diabetes mellitus (day -2979, -88) | K17: metformin (day -5250, for 1522 days); insulin isophane (day -5241, for 2196 days); acarbose (day -5236, for 1728 days); pioglitazone (day -4000, for 27 days); pioglitazone (day -3916, for 184 days); insulin glargine (day -3902, for 37 days); metformin (da | N17: HbA1c measurement (DCCT aligned) (34 millimole per mole, normal, day -7); | R17: insulin isophane (day 323, for 27 days); insulin isophane (day 385, for 112 days); | T17: Probable
B18: 503810366 | C18: 72 | D18: Male | E18: -5496 days - 1202 days | F18: Office Visit | G18: Blood pressure finding (EHR); Diabetes mellitus (EHR); Type 1 diabetes mellitus (EHR); | H18: Acute pancreatitis (day -38); Essential hypertension (day -1177, -830, -674) | O18: Acute pancreatitis (day -38); Diabetes mellitus (day 0) | R18: insulin aspart, human (day 33, for 60 days); insulin aspart protamine, human (day 33, for 60 days); insulin glargine (day 125, for 98 days); insulin glargine (day 279, for 27 days); insulin glargine (day 369, for 67 days); insulin glargine (day 510, for 2 | T18: No Case
B19: 559910689 | C19: 34 | D19: Male | E19: -1186 days - 4197 days | F19: Office Visit->Office Visit | G19: Blood pressure finding (EHR); Type 1 diabetes mellitus (EHR); | H19: Diabetes mellitus (day -350) | K19: insulin, regular, human (day -1108, for 27 days); insulin, regular, human (day -1043, for 27 days); insulin, regular, human (day -892, for 85 days); insulin, regular, human (day -599, for 27 days); insulin, regular, human (day -487, for 27 days); insulin, | N19: HbA1c measurement (DCCT aligned) (8.4 , day 0); | P19: Diabetic hand syndrome (day 882, 958); Nonproliferative retinopathy due to diabetes mellitus (day 376); Retinopathy due to diabetes mellitus (day 3657, 4043); Type 1 diabetes mellitus (day 950, 1137) | R19: insulin, regular, human (day 21, for 27 days); insulin, regular, human (day 112, for 27 days); insulin, regular, human (day 207, for 27 days); insulin, regular, human (day 341, for 27 days); insulin, regular, human (day 416, for 27 days); insulin, regular | T19: Probable
B20: 644210241 | C20: 66 | D20: Male | E20: -4926 days - 262 days | F20: Office Visit | G20: Blood pressure finding (EHR); Type 1 diabetes mellitus (EHR); | H20: Diabetes mellitus (day -2589, -469); Essential hypertension (day -155); Type 2 diabetes mellitus (day -2589) | J20: Nonproliferative retinopathy due to diabetes mellitus (day -173) | K20: glyburide (day -1513, for 111 days); | R20: insulin isophane (day 0, for 27 days); insulin, regular, human (day 0, for 27 days); insulin isophane (day 80, for 27 days); insulin, regular, human (day 80, for 27 days); insulin isophane (day 142, for 27 days); insulin, regular, human (day 142, for 27 d | T20: Probable
B21: 812210207 | C21: 38 | D21: Female | E21: -85 days - 4750 days | F21: Office Visit | G21: Blood pressure finding (EHR); Type 1 diabetes mellitus (EHR); | N21: Serum fasting glucose measurement (15 millimole per liter, day 12); | R21: insulin isophane (day 0, for 76 days); insulin, regular, human (day 0, for 76 days); insulin, regular, human (day 113, for 133 days); insulin isophane (day 113, for 133 days); insulin, regular, human (day 289, for 27 days); insulin isophane (day 289, for | T21: Probable
