Workbook

Sheet KEEPER LLM Sensitivity All
A1: Model
A2: Label | C2: GPT 5o | D2: % | E2: Copilot 4o | F2: % | G2: Copilot 5o | H2: % | I2: Gemini | J2: %
B3: No Case | C3: 0 | D3: =C3/83 -> 0 | E3: 5 | F3: =E3/83 -> 0.060240964 | G3: 7 | H3: =G3/83 -> 0.084337349 | I3: 3 | J3: =I3/83 -> 0.036144578
B4: Probable | C4: 83 | D4: =C4/83 -> 1 | E4: 76 | F4: =E4/83 -> 0.91566265 | G4: 44 | H4: =G4/83 -> 0.53012048 | I4: 52 | J4: =I4/83 -> 0.62650602
B5: Case | C5: 0 | D5: =C5/83 -> 0 | E5: 2 | F5: =E5/83 -> 0.024096386 | G5: 32 | H5: =G5/83 -> 0.38554217 | I5: 83 | J5: =I5/83 -> 1

Sheet All by All
A1: personId | B1: Clinician-DPA | C1: GPT 5o | D1: Copilot 4o | E1: Copilot 5o | F1: Gemini | G1: Clinician-APU
A2: 643110884 | B2: =INDEX('Clinician-DPA'!S:S,MATCH('All by All'!A2,'Clinician-DPA'!A:A,0)) -> Probable (treatment-only) | C2: =INDEX('GPT 5o'!S:S,MATCH('All by All'!A2,'GPT 5o'!A:A,0)) -> No Case | D2: =INDEX('Copilot 4o'!S:S,MATCH('All by All'!A2,'Copilot 4o'!A:A,0)) -> Probable | E2: =INDEX('Copilot 5o'!S:S,MATCH('All by All'!A2,'Copilot 4o'!A:A,0)) -> Probable | F2: =INDEX(Gemini!I:I,MATCH('All by All'!A2,Gemini!A:A,0)) -> Probable | G2: =INDEX('Clinician-APU'!U:U,MATCH('All by All'!A2,'Clinician-APU'!C:C,0)) -> PROBABLE
A3: 706710306 | B3: =INDEX('Clinician-DPA'!S:S,MATCH('All by All'!A3,'Clinician-DPA'!A:A,0)) -> Case | C3: =INDEX('GPT 5o'!S:S,MATCH('All by All'!A3,'GPT 5o'!A:A,0)) -> No Case | D3: =INDEX('Copilot 4o'!S:S,MATCH('All by All'!A3,'Copilot 4o'!A:A,0)) -> Probable | E3: =INDEX('Copilot 5o'!S:S,MATCH('All by All'!A3,'Copilot 4o'!A:A,0)) -> Case | F3: =INDEX(Gemini!I:I,MATCH('All by All'!A3,Gemini!A:A,0)) -> Case | G3: =INDEX('Clinician-APU'!U:U,MATCH('All by All'!A3,'Clinician-APU'!C:C,0)) -> CASE
A4: 384210994 | B4: =INDEX('Clinician-DPA'!S:S,MATCH('All by All'!A4,'Clinician-DPA'!A:A,0)) -> Probable (treatment-only) | C4: =INDEX('GPT 5o'!S:S,MATCH('All by All'!A4,'GPT 5o'!A:A,0)) -> No Case | D4: =INDEX('Copilot 4o'!S:S,MATCH('All by All'!A4,'Copilot 4o'!A:A,0)) -> Probable | E4: =INDEX('Copilot 5o'!S:S,MATCH('All by All'!A4,'Copilot 4o'!A:A,0)) -> Probable | F4: =INDEX(Gemini!I:I,MATCH('All by All'!A4,Gemini!A:A,0)) -> Probable | G4: =INDEX('Clinician-APU'!U:U,MATCH('All by All'!A4,'Clinician-APU'!C:C,0)) -> PROBABLE
A5: 1502010397 | B5: =INDEX('Clinician-DPA'!S:S,MATCH('All by All'!A5,'Clinician-DPA'!A:A,0)) -> No case | C5: =INDEX('GPT 5o'!S:S,MATCH('All by All'!A5,'GPT 5o'!A:A,0)) -> No Case | D5: =INDEX('Copilot 4o'!S:S,MATCH('All by All'!A5,'Copilot 4o'!A:A,0)) -> Probable | E5: =INDEX('Copilot 5o'!S:S,MATCH('All by All'!A5,'Copilot 4o'!A:A,0)) -> Probable | F5: =INDEX(Gemini!I:I,MATCH('All by All'!A5,Gemini!A:A,0)) -> Probable | G5: =INDEX('Clinician-APU'!U:U,MATCH('All by All'!A5,'Clinician-APU'!C:C,0)) -> NON-CASE
A6: 503810366 | B6: =INDEX('Clinician-DPA'!S:S,MATCH('All by All'!A6,'Clinician-DPA'!A:A,0)) -> Case | C6: =INDEX('GPT 5o'!S:S,MATCH('All by All'!A6,'GPT 5o'!A:A,0)) -> No Case | D6: =INDEX('Copilot 4o'!S:S,MATCH('All by All'!A6,'Copilot 4o'!A:A,0)) -> Probable | E6: =INDEX('Copilot 5o'!S:S,MATCH('All by All'!A6,'Copilot 4o'!A:A,0)) -> Probable | F6: =INDEX(Gemini!I:I,MATCH('All by All'!A6,Gemini!A:A,0)) -> Probable | G6: =INDEX('Clinician-APU'!U:U,MATCH('All by All'!A6,'Clinician-APU'!C:C,0)) -> PROBABLE
A7: 5282710166 | B7: =INDEX('Clinician-DPA'!S:S,MATCH('All by All'!A7,'Clinician-DPA'!A:A,0)) -> Case | C7: =INDEX('GPT 5o'!S:S,MATCH('All by All'!A7,'GPT 5o'!A:A,0)) -> No Case | D7: =INDEX('Copilot 4o'!S:S,MATCH('All by All'!A7,'Copilot 4o'!A:A,0)) -> Probable | E7: =INDEX('Copilot 5o'!S:S,MATCH('All by All'!A7,'Copilot 4o'!A:A,0)) -> Case | F7: =INDEX(Gemini!I:I,MATCH('All by All'!A7,Gemini!A:A,0)) -> Case | G7: =INDEX('Clinician-APU'!U:U,MATCH('All by All'!A7,'Clinician-APU'!C:C,0)) -> CASE
A8: 153910595 | B8: =INDEX('Clinician-DPA'!S:S,MATCH('All by All'!A8,'Clinician-DPA'!A:A,0)) -> No case | C8: =INDEX('GPT 5o'!S:S,MATCH('All by All'!A8,'GPT 5o'!A:A,0)) -> No Case | D8: =INDEX('Copilot 4o'!S:S,MATCH('All by All'!A8,'Copilot 4o'!A:A,0)) -> No Case | E8: =INDEX('Copilot 5o'!S:S,MATCH('All by All'!A8,'Copilot 4o'!A:A,0)) -> No Case | F8: =INDEX(Gemini!I:I,MATCH('All by All'!A8,Gemini!A:A,0)) -> No Case | G8: =INDEX('Clinician-APU'!U:U,MATCH('All by All'!A8,'Clinician-APU'!C:C,0)) -> NON-CASE
A9: 239110163 | B9: =INDEX('Clinician-DPA'!S:S,MATCH('All by All'!A9,'Clinician-DPA'!A:A,0)) -> Case | C9: =INDEX('GPT 5o'!S:S,MATCH('All by All'!A9,'GPT 5o'!A:A,0)) -> No Case | D9: =INDEX('Copilot 4o'!S:S,MATCH('All by All'!A9,'Copilot 4o'!A:A,0)) -> Probable | E9: =INDEX('Copilot 5o'!S:S,MATCH('All by All'!A9,'Copilot 4o'!A:A,0)) -> Case | F9: =INDEX(Gemini!I:I,MATCH('All by All'!A9,Gemini!A:A,0)) -> Case | G9: =INDEX('Clinician-APU'!U:U,MATCH('All by All'!A9,'Clinician-APU'!C:C,0)) -> CASE
A10: 258510963 | B10: =INDEX('Clinician-DPA'!S:S,MATCH('All by All'!A10,'Clinician-DPA'!A:A,0)) -> Probable (treatment-only) | C10: =INDEX('GPT 5o'!S:S,MATCH('All by All'!A10,'GPT 5o'!A:A,0)) -> No Case | D10: =INDEX('Copilot 4o'!S:S,MATCH('All by All'!A10,'Copilot 4o'!A:A,0)) -> Probable | E10: =INDEX('Copilot 5o'!S:S,MATCH('All by All'!A10,'Copilot 4o'!A:A,0)) -> Probable | F10: =INDEX(Gemini!I:I,MATCH('All by All'!A10,Gemini!A:A,0)) -> Probable | G10: =INDEX('Clinician-APU'!U:U,MATCH('All by All'!A10,'Clinician-APU'!C:C,0)) -> PROBABLE
A11: 366910461 | B11: =INDEX('Clinician-DPA'!S:S,MATCH('All by All'!A11,'Clinician-DPA'!A:A,0)) -> Probable (treatment-only) | C11: =INDEX('GPT 5o'!S:S,MATCH('All by All'!A11,'GPT 5o'!A:A,0)) -> No Case | D11: =INDEX('Copilot 4o'!S:S,MATCH('All by All'!A11,'Copilot 4o'!A:A,0)) -> Probable | E11: =INDEX('Copilot 5o'!S:S,MATCH('All by All'!A11,'Copilot 4o'!A:A,0)) -> Probable | F11: =INDEX(Gemini!I:I,MATCH('All by All'!A11,Gemini!A:A,0)) -> Probable | G11: =INDEX('Clinician-APU'!U:U,MATCH('All by All'!A11,'Clinician-APU'!C:C,0)) -> PROBABLE
A12: 592410349 | B12: =INDEX('Clinician-DPA'!S:S,MATCH('All by All'!A12,'Clinician-DPA'!A:A,0)) -> Probable (treatment-only) | C12: =INDEX('GPT 5o'!S:S,MATCH('All by All'!A12,'GPT 5o'!A:A,0)) -> No Case | D12: =INDEX('Copilot 4o'!S:S,MATCH('All by All'!A12,'Copilot 4o'!A:A,0)) -> Probable | E12: =INDEX('Copilot 5o'!S:S,MATCH('All by All'!A12,'Copilot 4o'!A:A,0)) -> Probable | F12: =INDEX(Gemini!I:I,MATCH('All by All'!A12,Gemini!A:A,0)) -> Probable | G12: =INDEX('Clinician-APU'!U:U,MATCH('All by All'!A12,'Clinician-APU'!C:C,0)) -> PROBABLE
A13: 1094310233 | B13: =INDEX('Clinician-DPA'!S:S,MATCH('All by All'!A13,'Clinician-DPA'!A:A,0)) -> Probable (treatment-only) | C13: =INDEX('GPT 5o'!S:S,MATCH('All by All'!A13,'GPT 5o'!A:A,0)) -> No Case | D13: =INDEX('Copilot 4o'!S:S,MATCH('All by All'!A13,'Copilot 4o'!A:A,0)) -> Probable | E13: =INDEX('Copilot 5o'!S:S,MATCH('All by All'!A13,'Copilot 4o'!A:A,0)) -> Probable | F13: =INDEX(Gemini!I:I,MATCH('All by All'!A13,Gemini!A:A,0)) -> Probable | G13: =INDEX('Clinician-APU'!U:U,MATCH('All by All'!A13,'Clinician-APU'!C:C,0)) -> PROBABLE
A14: 1237910593 | B14: =INDEX('Clinician-DPA'!S:S,MATCH('All by All'!A14,'Clinician-DPA'!A:A,0)) -> Case | C14: =INDEX('GPT 5o'!S:S,MATCH('All by All'!A14,'GPT 5o'!A:A,0)) -> No Case | D14: =INDEX('Copilot 4o'!S:S,MATCH('All by All'!A14,'Copilot 4o'!A:A,0)) -> Probable | E14: =INDEX('Copilot 5o'!S:S,MATCH('All by All'!A14,'Copilot 4o'!A:A,0)) -> Case | F14: =INDEX(Gemini!I:I,MATCH('All by All'!A14,Gemini!A:A,0)) -> Case | G14: =INDEX('Clinician-APU'!U:U,MATCH('All by All'!A14,'Clinician-APU'!C:C,0)) -> CASE
A15: 1489110030 | B15: =INDEX('Clinician-DPA'!S:S,MATCH('All by All'!A15,'Clinician-DPA'!A:A,0)) -> No case | C15: =INDEX('GPT 5o'!S:S,MATCH('All by All'!A15,'GPT 5o'!A:A,0)) -> No Case | D15: =INDEX('Copilot 4o'!S:S,MATCH('All by All'!A15,'Copilot 4o'!A:A,0)) -> No Case | E15: =INDEX('Copilot 5o'!S:S,MATCH('All by All'!A15,'Copilot 4o'!A:A,0)) -> No Case | F15: =INDEX(Gemini!I:I,MATCH('All by All'!A16,Gemini!A:A,0)) -> #N/A | G15: =INDEX('Clinician-APU'!U:U,MATCH('All by All'!A15,'Clinician-APU'!C:C,0)) -> NON-CASE
A16: 3333010111 | B16: =INDEX('Clinician-DPA'!S:S,MATCH('All by All'!A16,'Clinician-DPA'!A:A,0)) -> Probable (treatment-only) | C16: =INDEX('GPT 5o'!S:S,MATCH('All by All'!A16,'GPT 5o'!A:A,0)) -> No Case | D16: =INDEX('Copilot 4o'!S:S,MATCH('All by All'!A16,'Copilot 4o'!A:A,0)) -> Probable | E16: =INDEX('Copilot 5o'!S:S,MATCH('All by All'!A16,'Copilot 4o'!A:A,0)) -> Case | F16: =INDEX(Gemini!I:I,MATCH('All by All'!A16,Gemini!A:A,0)) -> #N/A | G16: =INDEX('Clinician-APU'!U:U,MATCH('All by All'!A16,'Clinician-APU'!C:C,0)) -> CASE
A17: 4298610465 | B17: =INDEX('Clinician-DPA'!S:S,MATCH('All by All'!A17,'Clinician-DPA'!A:A,0)) -> Case | C17: =INDEX('GPT 5o'!S:S,MATCH('All by All'!A17,'GPT 5o'!A:A,0)) -> No Case | D17: =INDEX('Copilot 4o'!S:S,MATCH('All by All'!A17,'Copilot 4o'!A:A,0)) -> Probable | E17: =INDEX('Copilot 5o'!S:S,MATCH('All by All'!A17,'Copilot 4o'!A:A,0)) -> Case | F17: =INDEX(Gemini!I:I,MATCH('All by All'!A17,Gemini!A:A,0)) -> #N/A | G17: =INDEX('Clinician-APU'!U:U,MATCH('All by All'!A17,'Clinician-APU'!C:C,0)) -> CASE
A18: 863610325 | B18: =INDEX('Clinician-DPA'!S:S,MATCH('All by All'!A18,'Clinician-DPA'!A:A,0)) -> Case | C18: =INDEX('GPT 5o'!S:S,MATCH('All by All'!A18,'GPT 5o'!A:A,0)) -> No Case | D18: =INDEX('Copilot 4o'!S:S,MATCH('All by All'!A18,'Copilot 4o'!A:A,0)) -> Probable | E18: =INDEX('Copilot 5o'!S:S,MATCH('All by All'!A18,'Copilot 4o'!A:A,0)) -> Case | F18: =INDEX(Gemini!I:I,MATCH('All by All'!A18,Gemini!A:A,0)) -> #N/A | G18: =INDEX('Clinician-APU'!U:U,MATCH('All by All'!A18,'Clinician-APU'!C:C,0)) -> CASE
A19: 3882310263 | B19: =INDEX('Clinician-DPA'!S:S,MATCH('All by All'!A19,'Clinician-DPA'!A:A,0)) -> Probable (treatment-only) | C19: =INDEX('GPT 5o'!S:S,MATCH('All by All'!A19,'GPT 5o'!A:A,0)) -> No Case | D19: =INDEX('Copilot 4o'!S:S,MATCH('All by All'!A19,'Copilot 4o'!A:A,0)) -> Probable | E19: =INDEX('Copilot 5o'!S:S,MATCH('All by All'!A19,'Copilot 4o'!A:A,0)) -> Case | F19: =INDEX(Gemini!I:I,MATCH('All by All'!A19,Gemini!A:A,0)) -> #N/A | G19: =INDEX('Clinician-APU'!U:U,MATCH('All by All'!A19,'Clinician-APU'!C:C,0)) -> PROBABLE
A20: 502810717 | B20: =INDEX('Clinician-DPA'!S:S,MATCH('All by All'!A20,'Clinician-DPA'!A:A,0)) -> Case | C20: =INDEX('GPT 5o'!S:S,MATCH('All by All'!A20,'GPT 5o'!A:A,0)) -> No Case | D20: =INDEX('Copilot 4o'!S:S,MATCH('All by All'!A20,'Copilot 4o'!A:A,0)) -> Probable | E20: =INDEX('Copilot 5o'!S:S,MATCH('All by All'!A20,'Copilot 4o'!A:A,0)) -> Case | F20: =INDEX(Gemini!I:I,MATCH('All by All'!A20,Gemini!A:A,0)) -> #N/A | G20: =INDEX('Clinician-APU'!U:U,MATCH('All by All'!A20,'Clinician-APU'!C:C,0)) -> CASE
A21: 811810047 | B21: =INDEX('Clinician-DPA'!S:S,MATCH('All by All'!A21,'Clinician-DPA'!A:A,0)) -> Case | C21: =INDEX('GPT 5o'!S:S,MATCH('All by All'!A21,'GPT 5o'!A:A,0)) -> No Case | D21: =INDEX('Copilot 4o'!S:S,MATCH('All by All'!A21,'Copilot 4o'!A:A,0)) -> Probable | E21: =INDEX('Copilot 5o'!S:S,MATCH('All by All'!A21,'Copilot 4o'!A:A,0)) -> Case | F21: =INDEX(Gemini!I:I,MATCH('All by All'!A21,Gemini!A:A,0)) -> #N/A | G21: =INDEX('Clinician-APU'!U:U,MATCH('All by All'!A21,'Clinician-APU'!C:C,0)) -> CASE
A22: 1626210870 | B22: =INDEX('Clinician-DPA'!S:S,MATCH('All by All'!A22,'Clinician-DPA'!A:A,0)) -> Case | C22: =INDEX('GPT 5o'!S:S,MATCH('All by All'!A22,'GPT 5o'!A:A,0)) -> No Case | D22: =INDEX('Copilot 4o'!S:S,MATCH('All by All'!A22,'Copilot 4o'!A:A,0)) -> Probable | E22: =INDEX('Copilot 5o'!S:S,MATCH('All by All'!A22,'Copilot 4o'!A:A,0)) -> Case | F22: =INDEX(Gemini!I:I,MATCH('All by All'!A22,Gemini!A:A,0)) -> #N/A | G22: =INDEX('Clinician-APU'!U:U,MATCH('All by All'!A22,'Clinician-APU'!C:C,0)) -> CASE
A23: 2213210607 | B23: =INDEX('Clinician-DPA'!S:S,MATCH('All by All'!A23,'Clinician-DPA'!A:A,0)) -> Case | C23: =INDEX('GPT 5o'!S:S,MATCH('All by All'!A23,'GPT 5o'!A:A,0)) -> No Case | D23: =INDEX('Copilot 4o'!S:S,MATCH('All by All'!A23,'Copilot 4o'!A:A,0)) -> Probable | E23: =INDEX('Copilot 5o'!S:S,MATCH('All by All'!A23,'Copilot 4o'!A:A,0)) -> Case | F23: =INDEX(Gemini!I:I,MATCH('All by All'!A23,Gemini!A:A,0)) -> #N/A | G23: =INDEX('Clinician-APU'!U:U,MATCH('All by All'!A23,'Clinician-APU'!C:C,0)) -> CASE
A24: 5494710200 | B24: =INDEX('Clinician-DPA'!S:S,MATCH('All by All'!A24,'Clinician-DPA'!A:A,0)) -> Probable (treatment-only) | C24: =INDEX('GPT 5o'!S:S,MATCH('All by All'!A24,'GPT 5o'!A:A,0)) -> No Case | D24: =INDEX('Copilot 4o'!S:S,MATCH('All by All'!A24,'Copilot 4o'!A:A,0)) -> Probable | E24: =INDEX('Copilot 5o'!S:S,MATCH('All by All'!A24,'Copilot 4o'!A:A,0)) -> Case | F24: =INDEX(Gemini!I:I,MATCH('All by All'!A24,Gemini!A:A,0)) -> #N/A | G24: =INDEX('Clinician-APU'!U:U,MATCH('All by All'!A24,'Clinician-APU'!C:C,0)) -> CASE
A25: 1525510677 | B25: =INDEX('Clinician-DPA'!S:S,MATCH('All by All'!A25,'Clinician-DPA'!A:A,0)) -> Case | C25: =INDEX('GPT 5o'!S:S,MATCH('All by All'!A25,'GPT 5o'!A:A,0)) -> No Case | D25: =INDEX('Copilot 4o'!S:S,MATCH('All by All'!A25,'Copilot 4o'!A:A,0)) -> Probable | E25: =INDEX('Copilot 5o'!S:S,MATCH('All by All'!A25,'Copilot 4o'!A:A,0)) -> Case | F25: =INDEX(Gemini!I:I,MATCH('All by All'!A25,Gemini!A:A,0)) -> #N/A | G25: =INDEX('Clinician-APU'!U:U,MATCH('All by All'!A25,'Clinician-APU'!C:C,0)) -> CASE
A26: 3810766 | B26: =INDEX('Clinician-DPA'!S:S,MATCH('All by All'!A26,'Clinician-DPA'!A:A,0)) -> Case | C26: =INDEX('GPT 5o'!S:S,MATCH('All by All'!A26,'GPT 5o'!A:A,0)) -> No Case | D26: =INDEX('Copilot 4o'!S:S,MATCH('All by All'!A26,'Copilot 4o'!A:A,0)) -> Probable | E26: =INDEX('Copilot 5o'!S:S,MATCH('All by All'!A26,'Copilot 4o'!A:A,0)) -> Case | F26: =INDEX(Gemini!I:I,MATCH('All by All'!A26,Gemini!A:A,0)) -> #N/A | G26: =INDEX('Clinician-APU'!U:U,MATCH('All by All'!A26,'Clinician-APU'!C:C,0)) -> CASE
A27: 4610438 | B27: =INDEX('Clinician-DPA'!S:S,MATCH('All by All'!A27,'Clinician-DPA'!A:A,0)) -> Case | C27: =INDEX('GPT 5o'!S:S,MATCH('All by All'!A27,'GPT 5o'!A:A,0)) -> No Case | D27: =INDEX('Copilot 4o'!S:S,MATCH('All by All'!A27,'Copilot 4o'!A:A,0)) -> Probable | E27: =INDEX('Copilot 5o'!S:S,MATCH('All by All'!A27,'Copilot 4o'!A:A,0)) -> No Case | F27: =INDEX(Gemini!I:I,MATCH('All by All'!A27,Gemini!A:A,0)) -> #N/A | G27: =INDEX('Clinician-APU'!U:U,MATCH('All by All'!A27,'Clinician-APU'!C:C,0)) -> NON-CASE
... A84: 4946010229 | B84: =INDEX('Clinician-DPA'!S:S,MATCH('All by All'!A84,'Clinician-DPA'!A:A,0)) -> Probable (treatment-only) | C84: =INDEX('GPT 5o'!S:S,MATCH('All by All'!A84,'GPT 5o'!A:A,0)) -> No Case | D84: =INDEX('Copilot 4o'!S:S,MATCH('All by All'!A84,'Copilot 4o'!A:A,0)) -> Probable | E84: =INDEX('Copilot 5o'!S:S,MATCH('All by All'!A84,'Copilot 4o'!A:A,0)) -> Probable | F84: =INDEX(Gemini!I:I,MATCH('All by All'!A84,Gemini!A:A,0)) -> #N/A | G84: =INDEX('Clinician-APU'!U:U,MATCH('All by All'!A84,'Clinician-APU'!C:C,0)) -> PROBABLE

Sheet Clinician-APU
A1: Adjudication | B1: Comments | C1: personId | D1: age | E1: gender | F1: observationPeriod | G1: visitContext | H1: presentation | I1: comorbidities | J1: symptoms | K1: priorDisease | L1: priorDrugs | M1: priorTreatmentProcedures | N1: diagnosticProcedures | O1: measurements | P1: alternativeDiagnosis | Q1: afterDisease | R1: afterTreatmentProcedures | S1: afterDrugs | T1: death | U1: Clinical Label | V1: Comments
A2: P | C2: 643110884 | D2: 50 | E2: Male | F2: -833 days - 4200 days | G2: Office Visit | H2: 10g monofilament sensation R foot normal (EHR); All pulses present in left foot (EHR); All pulses present in right foot (EHR); Type 1 diabetes mellitus (EHR); | Q2: Type 1 diabetes mellitus (day 1516) | S2: insulin aspart, human (day 36, for 2022 days); insulin aspart, human (day 2091, for 372 days); insulin aspart, human (day 2497, for 28 days); insulin aspart, human (day 2561, for 26 days); insulin aspart, human (day 2629, for 0 days); insulin aspart, human (day 2666, for 0 days); insulin aspart, human (day 2699, for 0 days); insulin aspart, human (day 2738, for 0 days); insulin aspart, human (day 2770, for 49 days); insulin aspart, human (day 2861, for 155 days); insulin aspart, human (day 3052, for 104 days); insulin aspart, human (day 3203, for 766 days); | U2: PROBABLE
A3: C | C3: 706710306 | D3: 48 | E3: Male | F3: -2693 days - 5002 days | G3: Office Visit | H3: Acute pancreatitis (EHR); Type 1 diabetes mellitus (EHR); | Q3: Chronic kidney disease stage 3 (day 2341); Diabetes mellitus (day 1670, 1800, 1922, 1985, 3353, 3612, 4397); Nonproliferative retinopathy due to diabetes mellitus (day 3251, 4517); Nonproliferative retinopathy of right eye due to diabetes mellitus (day 3251); Type 1 diabetes mellitus (day 1669) | S3: insulin glargine (day 1670, for 157 days); insulin aspart, human (day 1823, for 27 days); insulin aspart, human (day 1894, for 55 days); insulin aspart, human (day 1985, for 27 days); insulin aspart, human (day 2066, for 94 days); insulin aspart, human (day 2227, for 0 days); insulin aspart, human (day 2271, for 0 days); insulin aspart, human (day 2334, for 0 days); insulin aspart, human (day 2387, for 0 days); insulin aspart, human (day 2478, for 0 days); insulin aspart, human (day 2517, for 0 days); insulin aspart, human (day 2591, for 0 days); insulin aspart, human (day 2642, for 0 days); insulin aspart, human (day 2706, for 0 days); insulin aspart, human (day 2765, for 0 days); insulin aspart, human (day 2823, for 0 days); insulin aspart, human (day 2871, for 0 days); insulin aspart, human (day 2934, for 0 days); insulin aspart, human (day 2990, for 0 days); insulin aspart, human (day 3060, for 0 days); insulin aspart, human (day 3129, for 0 days); insulin aspart, human (day 3182, for 0 days); insulin aspart, human (day 3244, for 0 days); insulin aspart, human (day 3313, for 0 days); insulin aspart, human (day 3353, for 0 days); insulin aspart, human (day 3452, for 0 days); insulin aspart, human (day 3538, for 0 days); insulin aspart, human (day 3612, for 0 days); insulin aspart, human (day 3697, for 0 days); insulin aspart, human (day 3760, for 0 days); insulin aspart, human (day 3843, for 0 days); insulin aspart, human (day 3922, for 0 days); insulin aspart, human (day 3998, for 0 days); insulin aspart, human (day 4081, for 0 days); insulin aspart, human (day 4148, for 0 days); insulin aspart, human (day 4211, for 0 days); insulin aspart, human (day 4308, for 0 days); insulin aspart, human (day 4397, for 0 days); insulin aspart, human (day 4461, for 0 days); insulin aspart, human (day 4533, for 0 days); insulin aspart, human (day 4595, for 0 days); insulin aspart, human (day 4649, for 0 days); insulin aspart, human (day 4698, for 0 days); insulin aspart, human (day 4756, for 0 days); insulin aspart, human (day 4824, for 0 days); insulin aspart, human (day 4887, for 14 days); | U3: CASE
A4: P | C4: 384210994 | D4: 30 | E4: Male | F4: -7106 days - 903 days | G4: Office Visit | H4: Asymptomatic periapical periodontitis (EHR); Dental caries (EHR); Type 1 diabetes mellitus (EHR); | S4: insulin glargine (day 8, for 178 days); insulin aspart, human (day 8, for 178 days); insulin aspart, human (day 218, for 243 days); insulin glargine (day 218, for 243 days); insulin aspart, human (day 543, for 28 days); insulin glargine (day 543, for 28 days); | U4: PROBABLE
A5: N | B5: Metformin | C5: 1502010397 | D5: 15 | E5: Male | F5: -1969 days - 1588 days | G5: Office Visit | H5: Atypical chest pain (EHR); Type 1 diabetes mellitus (EHR); | Q5: Type 1 diabetes mellitus (day 47, 677) | S5: insulin aspart, human (day 1, for 1586 days); insulin, regular, human (day 1, for 44 days); metformin (day 1091, for 29 days); insulin glargine (day 1091, for 28 days); insulin glargine (day 1155, for 0 days); metformin (day 1155, for 41 days); insulin glargine (day 1189, for 89 days); metformin (day 1238, for 69 days); insulin glargine (day 1327, for 0 days); insulin glargine (day 1359, for 0 days); insulin glargine (day 1400, for 26 days); insulin glargine (day 1482, for 0 days); | U5: NON-CASE | V5: Likely index date misclassification (metformin use)
A6: P | C6: 503810366 | D6: 72 | E6: Male | F6: -5496 days - 1202 days | G6: Office Visit | H6: Blood pressure finding (EHR); Diabetes mellitus (EHR); Type 1 diabetes mellitus (EHR); | K6: Cerebrovascular accident (day -162); Reactive depression (situational) (day -2647) | Q6: Depressive disorder (day 157, 262); Recurrent major depressive episodes (day 350) | S6: insulin aspart, human (day 33, for 60 days); insulin glargine (day 125, for 98 days); insulin glargine (day 279, for 27 days); insulin glargine (day 369, for 67 days); insulin glargine (day 510, for 27 days); insulin glargine (day 614, for 74 days); insulin glargine (day 754, for 35 days); insulin glargine (day 930, for 27 days); insulin glargine (day 991, for 73 days); insulin glargine (day 1189, for 0 days); | U6: PROBABLE
A7: C | C7: 5282710166 | D7: 22 | E7: Male | F7: -3845 days - 3300 days | G7: Office Visit | H7: Blood pressure finding (EHR); Diabetes mellitus (EHR); Type 1 diabetes mellitus (EHR); | Q7: Diabetic ketoacidosis (day 5); Ketoacidosis due to type 1 diabetes mellitus (day 2315) | S7: insulin aspart, human (day 4, for 128 days); insulin aspart, human (day 245, for 27 days); insulin aspart, human (day 326, for 0 days); insulin aspart, human (day 441, for 0 days); insulin aspart, human (day 490, for 78 days); insulin aspart, human (day 636, for 85 days); insulin aspart, human (day 753, for 0 days); insulin aspart, human (day 788, for 0 days); insulin aspart, human (day 819, for 0 days); insulin aspart, human (day 854, for 0 days); insulin aspart, human (day 887, for 87 days); insulin aspart, human (day 1034, for 160 days); insulin aspart, human (day 1247, for 90 days); insulin aspart, human (day 1380, for 857 days); insulin aspart, human (day 2286, for 84 days); insulin aspart, human (day 2406, for 120 days); insulin aspart, human (day 2568, for 194 days); insulin aspart, human (day 2825, for 176 days); insulin lispro (day 3001, for 0 days); insulin lispro (day 3049, for 18 days); insulin lispro (day 3101, for 26 days); insulin lispro (day 3169, for 126 days); | U7: CASE
A8: N | B8: diagnosed with T2 after (not exclusive but rare?) | C8: 153910595 | D8: 60 | E8: Male | F8: -938 days - 1257 days | G8: Office Visit | H8: Diabetes mellitus (EHR); Insulin treated type 2 diabetes mellitus (EHR); Type 1 diabetes mellitus (EHR); | Q8: Diabetes mellitus (day 323, 406, 1006); Type 1 diabetes mellitus (day 778, 1006); Type 2 diabetes mellitus (day 406) | U8: NON-CASE | V8: Likely index date misclassification (TD2M)
A9: C | C9: 239110163 | D9: 11 | E9: Female | F9: -893 days - 7129 days | G9: Office Visit | H9: Diabetes mellitus (EHR); Type 1 diabetes mellitus (EHR); | Q9: Diabetes mellitus (day 1418, 1936); Retinopathy due to diabetes mellitus (day 923) | S9: insulin aspart, human (day 0, for 27 days); insulin aspart, human (day 66, for 27 days); insulin aspart, human (day 150, for 0 days); insulin aspart, human (day 229, for 0 days); insulin aspart, human (day 292, for 0 days); insulin aspart, human (day 354, for 0 days); insulin aspart, human (day 385, for 0 days); insulin glargine (day 445, for 27 days); insulin aspart, human (day 488, for 0 days); insulin glargine (day 528, for 27 days); insulin aspart, human (day 528, for 0 days); insulin glargine (day 586, for 27 days); insulin aspart, human (day 586, for 0 days); insulin aspart, human (day 633, for 0 days); insulin glargine (day 661, for 77 days); insulin aspart, human (day 691, for 0 days); insulin aspart, human (day 728, for 0 days); insulin glargine (day 769, for 84 days); insulin aspart, human (day 826, for 0 days); insulin aspart, human (day 886, for 0 days); insulin glargine (day 889, for 290 days); insulin aspart, human (day 944, for 53 days); insulin aspart, human (day 1047, for 0 days); insulin aspart, human (day 1099, for 0 days); insulin aspart, human (day 1152, for 0 days); insulin aspart, human (day 1187, for 0 days); insulin glargine (day 1215, for 1178 days); insulin aspart, human (day 1236, for 0 days); insulin aspart, human (day 1272, for 0 days); insulin aspart, human (day 1315, for 0 days); insulin aspart, human (day 1369, for 0 days); insulin aspart, human (day 1414, for 0 days); insulin aspart, human (day 1449, for 0 days); insulin aspart, human (day 1524, for 0 days); insulin aspart, human (day 1566, for 0 days); insulin aspart, human (day 1600, for 15 days); insulin aspart, human (day 1673, for 0 days); insulin aspart, human (day 1715, for 53 days); insulin aspart, human (day 1812, for 0 days); insulin aspart, human (day 1845, for 0 days); insulin aspart, human (day 1909, for 30 days); insulin aspart, human (day 2012, for 0 days); insulin aspart, human (day 2055, for 21 days); insulin aspart, human (day 2126, for 0 days); insulin aspart, human (day 2168, for 0 days); insulin aspart, human (day 2254, for 28 days); insulin aspart, human (day 2320, for 0 days); insulin aspart, human (day 2366, for 0 days); insulin aspart, human (day 2405, for 0 days); insulin glargine (day 2432, for 154 days); insulin aspart, human (day 2457, for 0 days); insulin aspart, human (day 2499, for 0 days); insulin aspart, human (day 2541, for 45 days); insulin glargine (day 2624, for 0 days); insulin glargine (day 2658, for 0 days); insulin aspart, human (day 2671, for 0 days); insulin glargine (day 2700, for 21 days); insulin aspart, human (day 2721, for 0 days); insulin glargine (day 2761, for 29 days); insulin aspart, human (day 2761, for 0 days); insulin aspart, human (day 2821, for 0 days); insulin glargine (day 2848, for 28 days); insulin aspart, human (day 2876, for 0 days); insulin aspart, human (day 2909, for 0 days); insulin glargine (day 2910, for 0 days); insulin aspart, human (day 2959, for 56 days); insulin glargine (day 2986, for 29 days); insulin aspart, human (day 3052, for 0 days); insulin glargine (day 3052, for 0 days); insulin aspart, human (day 3119, for 0 days); insulin glargine (day 3119, for 0 days); insulin aspart, human (day 3157, for 0 days); insulin glargine (day 3157, for 0 days); insulin glargine (day 3205, for 0 days); insulin glargine (day 3237, for 29 days); insulin aspart, human (day 3237, for 29 days); insulin glargine (day 3316, for 28 days); insulin aspart, human (day 3316, for 28 days); insulin glargine (day 3394, for 43 days); insulin aspart, human (day 3394, for 43 days); insulin glargine (day 3497, for 0 days); insulin aspart, human (day 3532, for 0 days); insulin glargine (day 3532, for 0 days); insulin glargine (day 3566, for 0 days); insulin aspart, human (day 3566, for 0 days); insulin glargine (day 3609, for 0 days); insulin aspart, human (day 3609, for 0 days); insulin glargine (day 3640, for 0 days); insulin aspart, human (day 3640, for 0 days); insulin glargine (day 3674, for 0 days); insulin aspart, human (day 3674, for 0 days); insulin glargine (day 3720, for 0 days); insulin aspart, human (day 3720, for 0 days); insulin aspart, human (day 3771, for 0 days); insulin glargine (day 3771, for 0 days); insulin glargine (day 3806, for 0 days); insulin aspart, human (day 3806, for 29 days); insulin glargine (day 3854, for 0 days); insulin aspart, human (day 3876, for 0 days); insulin glargine (day 3892, for 0 days); insulin aspart, human (day 3912, for 56 days); insulin glargine (day 3939, for 29 days); insulin glargine (day 4018, for 0 days); insulin aspart, human (day 4018, for 27 days); insulin glargine (day 4084, for 0 days); insulin aspart, human (day 4088, for 0 days); insulin glargine (day 4120, for 0 days); insulin aspart, human (day 4120, for 0 days); insulin aspart, human (day 4163, for 0 days); insulin glargine (day 4163, for 0 days); insulin glargine (day 4217, for 0 days); insulin aspart, human (day 4217, for 0 days); insulin aspart, human (day 4261, for 58 days); insulin glargine (day 4261, for 30 days); insulin glargine (day 4367, for 0 days); insulin aspart, human (day 4367, for 0 days); insulin aspart, human (day 4414, for 0 days); insulin glargine (day 4414, for 28 days); insulin glargine (day 4478, for 0 days); insulin aspart, human (day 4478, for 0 days); insulin glargine (day 4535, for 0 days); insulin aspart, human (day 4535, for 0 days); insulin glargine (day 4567, for 0 days); insulin aspart, human (day 4567, for 0 days); insulin aspart, human (day 4641, for 0 days); insulin glargine (day 4641, for 0 days); insulin glargine (day 4694, for 1 days); insulin aspart, human (day 4694, for 1 days); insulin aspart, human (day 4749, for 0 days); insulin glargine (day 4812, for 0 days); insulin aspart, human (day 4812, for 0 days); insulin glargine (day 4847, for 0 days); insulin aspart, human (day 4884, for 0 days); insulin glargine (day 4884, for 0 days); insulin glargine (day 4924, for 0 days); insulin aspart, human (day 4924, for 0 days); insulin aspart, human (day 5001, for 0 days); insulin glargine (day 5001, for 0 days); insulin glargine (day 5036, for 29 days); insulin aspart, human (day 5036, for 29 days); insulin aspart, human (day 5134, for 0 days); insulin glargine (day 5134, for 0 days); insulin glargine (day 5179, for 0 days); insulin aspart, human (day 5215, for 0 days); insulin glargine (day 5215, for 0 days); insulin aspart, human (day 5254, for 0 days); insulin glargine (day 5254, for 0 days); insulin glargine (day 5288, for 0 days); insulin aspart, human (day 5288, for 0 days); insulin glargine (day 5374, for 0 days); insulin aspart, human (day 5374, for 0 days); insulin glargine (day 5409, for 0 days); insulin aspart, human (day 5409, for 0 days); insulin aspart, human (day 5445, for 0 days); insulin glargine (day 5445, for 0 days); insulin aspart, human (day 5516, for 0 days); insulin glargine (day 5516, for 0 days); insulin aspart, human (day 5592, for 0 days); insulin glargine (day 5592, for 0 days); insulin glargine (day 5631, for 0 days); insulin aspart, human (day 5631, for 0 days); insulin glargine (day 5673, for 0 days); insulin aspart, human (day 5708, for 0 days); insulin glargine (day 5708, for 0 days); insulin glargine (day 5759, for 0 days); insulin aspart, human (day 5759, for 0 days); insulin glargine (day 5802, for 0 days); insulin aspart, human (day 5802, for 0 days); insulin glargine (day 5870, for 0 days); insulin aspart, human (day 5919, for 0 days); insulin glargine (day 5919, for 0 days); insulin glargine (day 5961, for 24 days); insulin aspart, human (day 5961, for 24 days); insulin degludec (day 6019, for 27 days); insulin aspart, human (day 6046, for 0 days); insulin degludec (day 6107, for 0 days); insulin aspart, human (day 6107, for 0 days); insulin aspart, human (day 6139, for 0 days); insulin degludec (day 6139, for 0 days); insulin aspart, human (day 6177, for 101 days); insulin degludec (day 6195, for 17 days); insulin degludec (day 6251, for 0 days); insulin glargine (day 6310, for 0 days); insulin aspart, human (day 6310, for 883 days); insulin glargine (day 6396, for 0 days); insulin glargine (day 6737, for 0 days); insulin glargine (day 7003, for 0 days); | U9: CASE
A10: P | C10: 258510963 | D10: 48 | E10: Male | F10: -611 days - 763 days | G10: Office Visit | H10: Diabetes mellitus (EHR); Type 1 diabetes mellitus (EHR); | S10: insulin glargine (day 0, for 30 days); insulin aspart, human (day 16, for 52 days); insulin glargine (day 92, for 27 days); insulin aspart, human (day 104, for 27 days); insulin aspart, human (day 171, for 27 days); insulin aspart, human (day 233, for 27 days); insulin aspart, human (day 358, for 76 days); insulin glargine (day 479, for 27 days); insulin aspart, human (day 479, for 27 days); insulin glargine (day 686, for 27 days); insulin aspart, human (day 686, for 27 days); insulin aspart, human (day 751, for 27 days); | U10: PROBABLE
A11: P | C11: 366910461 | D11: 15 | E11: Male | F11: -3416 days - 64 days | G11: Office Visit | H11: Diabetes mellitus (EHR); Type 1 diabetes mellitus (EHR); | S11: insulin aspart, human (day 3, for 30 days); | U11: PROBABLE
A12: P | C12: 592410349 | D12: 21 | E12: Male | F12: -851 days - 1213 days | G12: Office Visit | H12: Diabetes mellitus (EHR); Mass of skin (EHR); Type 1 diabetes mellitus (EHR); | Q12: Agitated depression (day 801); Diabetes mellitus (day 511, 750, 801, 854, 1014); Endogenous depression first episode (day 638); Reactive depression (situational) (day 24); Type 1 diabetes mellitus (day 194) | S12: insulin, regular, human (day 7, for 27 days); insulin, regular, human (day 84, for 27 days); insulin, regular, human (day 143, for 311 days); insulin, regular, human (day 510, for 141 days); insulin, regular, human (day 706, for 153 days); insulin, regular, human (day 909, for 181 days); insulin, regular, human (day 1154, for 52 days); | U12: PROBABLE
A13: P | C13: 1094310233 | D13: 4 | E13: Male | F13: -1374 days - 6593 days | G13: Office Visit | H13: Diabetes mellitus (EHR); Type 1 diabetes mellitus (EHR); | Q13: Herpes zoster (day 5397); Type 1 diabetes mellitus (day 4064) | S13: insulin, regular, human (day 4, for 541 days); insulin, regular, human (day 710, for 27 days); insulin, regular, human (day 770, for 118 days); insulin, regular, human (day 920, for 27 days); insulin, regular, human (day 1013, for 620 days); insulin, regular, human (day 1669, for 62 days); insulin lispro (day 1747, for 1394 days); insulin glargine (day 3111, for 0 days); insulin glargine (day 3161, for 0 days); insulin lispro (day 3177, for 27 days); insulin glargine (day 3216, for 73 days); insulin lispro (day 3244, for 125 days); insulin glargine (day 3342, for 0 days); insulin glargine (day 3385, for 0 days); insulin glargine (day 3419, for 0 days); insulin lispro (day 3419, for 27 days); insulin lispro (day 3482, for 27 days); insulin glargine (day 3482, for 29 days); insulin glargine (day 3554, for 0 days); insulin lispro (day 3573, for 27 days); insulin glargine (day 3601, for 0 days); insulin glargine (day 3636, for 0 days); insulin lispro (day 3650, for 120 days); insulin glargine (day 3671, for 49 days); insulin glargine (day 3757, for 0 days); insulin glargine (day 3792, for 29 days); insulin lispro (day 3821, for 27 days); insulin glargine (day 3874, for 0 days); insulin lispro (day 3895, for 27 days); insulin glargine (day 3912, for 0 days); insulin glargine (day 3947, for 0 days); insulin lispro (day 3965, for 83 days); insulin glargine (day 3996, for 25 days); insulin glargine (day 4052, for 0 days); insulin lispro (day 4098, for 27 days); insulin glargine (day 4098, for 0 days); insulin glargine (day 4147, for 23 days); insulin lispro (day 4170, for 27 days); insulin glargine (day 4220, for 15 days); insulin lispro (day 4235, for 27 days); insulin glargine (day 4288, for 17 days); insulin lispro (day 4305, for 27 days); insulin glargine (day 4358, for 20 days); insulin lispro (day 4378, for 27 days); insulin glargine (day 4427, for 0 days); insulin lispro (day 4441, for 27 days); insulin glargine (day 4469, for 0 days); insulin glargine (day 4511, for 30 days); insulin lispro (day 4511, for 27 days); insulin glargine (day 4582, for 0 days); insulin lispro (day 4595, for 83 days); insulin glargine (day 4623, for 52 days); insulin lispro (day 4711, for 27 days); insulin glargine (day 4711, for 0 days); insulin glargine (day 4744, for 0 days); insulin lispro (day 4772, for 27 days); insulin glargine (day 4784, for 0 days); insulin glargine (day 4815, for 25 days); insulin lispro (day 4840, for 27 days); insulin glargine (day 4907, for 0 days); insulin lispro (day 4931, for 27 days); insulin glargine (day 4942, for 0 days); insulin glargine (day 4977, for 0 days); insulin lispro (day 4989, for 27 days); insulin glargine (day 5024, for 30 days); insulin lispro (day 5054, for 27 days); insulin glargine (day 5096, for 0 days); insulin glargine (day 5131, for 0 days); insulin lispro (day 5131, for 27 days); insulin glargine (day 5166, for 20 days); insulin lispro (day 5214, for 27 days); insulin glargine (day 5253, for 29 days); insulin lispro (day 5282, for 27 days); insulin glargine (day 5325, for 0 days); insulin lispro (day 5359, for 68 days); insulin glargine (day 5359, for 0 days); insulin glargine (day 5400, for 0 days); insulin glargine (day 5435, for 0 days); insulin glargine (day 5470, for 0 days); insulin lispro (day 5470, for 27 days); insulin glargine (day 5513, for 0 days); insulin glargine (day 5549, for 0 days); insulin lispro (day 5562, for 27 days); insulin glargine (day 5590, for 30 days); insulin lispro (day 5620, for 27 days); insulin glargine (day 5674, for 0 days); insulin lispro (day 5710, for 27 days); insulin glargine (day 5710, for 0 days); insulin glargine (day 5750, for 29 days); insulin lispro (day 5779, for 27 days); insulin glargine (day 5827, for 0 days); insulin glargine (day 5869, for 0 days); insulin lispro (day 5869, for 64 days); insulin glargine (day 5906, for 0 days); insulin glargine (day 5942, for 0 days); insulin glargine (day 5984, for 0 days); insulin lispro (day 6020, for 74 days); insulin glargine (day 6020, for 0 days); insulin glargine (day 6067, for 0 days); insulin glargine (day 6108, for 0 days); insulin lispro (day 6143, for 27 days); insulin glargine (day 6143, for 27 days); insulin glargine (day 6219, for 0 days); insulin lispro (day 6219, for 70 days); insulin glargine (day 6262, for 29 days); insulin lispro (day 6339, for 27 days); insulin glargine (day 6339, for 0 days); insulin glargine (day 6374, for 0 days); insulin glargine (day 6415, for 0 days); insulin lispro (day 6415, for 27 days); insulin glargine (day 6453, for 0 days); insulin glargine (day 6487, for 0 days); insulin lispro (day 6487, for 111 days); insulin glargine (day 6521, for 0 days); insulin glargine (day 6571, for 0 days); | U13: PROBABLE
A14: C | C14: 1237910593 | D14: 4 | E14: Male | F14: -552 days - 4726 days | G14: Office Visit | H14: Diabetes mellitus (EHR); Type 1 diabetes mellitus (EHR); | Q14: Diabetic ketoacidosis (day 3178) | S14: insulin, regular, human (day 407, for 205 days); insulin, regular, human (day 672, for 56 days); insulin, regular, human (day 782, for 119 days); insulin, regular, human (day 945, for 168 days); insulin, regular, human (day 1147, for 155 days); insulin, regular, human (day 1441, for 57 days); insulin, regular, human (day 1803, for 27 days); insulin, regular, human (day 1876, for 49 days); insulin aspart, human (day 1953, for 69 days); insulin glargine (day 1953, for 0 days); insulin glargine (day 2036, for 0 days); insulin aspart, human (day 2083, for 27 days); insulin aspart, human (day 2150, for 276 days); insulin glargine (day 2371, for 0 days); insulin aspart, human (day 2462, for 224 days); insulin glargine (day 2640, for 19 days); insulin aspart, human (day 2742, for 160 days); insulin glargine (day 2875, for 0 days); insulin aspart, human (day 2954, for 74 days); insulin glargine (day 2954, for 0 days); insulin glargine (day 3001, for 0 days); insulin aspart, human (day 3070, for 150 days); insulin glargine (day 3106, for 0 days); insulin glargine (day 3162, for 0 days); insulin glargine (day 3253, for 0 days); insulin aspart, human (day 3253, for 180 days); insulin glargine (day 3351, for 0 days); insulin glargine (day 3452, for 0 days); insulin aspart, human (day 3470, for 341 days); insulin glargine (day 3505, for 0 days); insulin glargine (day 3541, for 0 days); insulin glargine (day 3606, for 0 days); insulin glargine (day 3708, for 27 days); insulin glargine (day 3784, for 0 days); insulin aspart, human (day 3857, for 270 days); insulin glargine (day 3997, for 0 days); insulin glargine (day 4065, for 0 days); insulin aspart, human (day 4170, for 266 days); insulin glargine (day 4261, for 0 days); insulin glargine (day 4346, for 0 days); insulin glargine (day 4389, for 0 days); insulin aspart, human (day 4480, for 215 days); insulin glargine (day 4480, for 0 days); insulin glargine (day 4529, for 0 days); insulin glargine (day 4598, for 0 days); insulin glargine (day 4631, for 0 days); | U14: CASE
A15: N | C15: 1489110030 | D15: 60 | E15: Female | F15: -5976 days - 17 days | G15: Office Visit | H15: Diabetes mellitus (EHR); Type 1 diabetes mellitus (EHR); | U15: NON-CASE
A16: C | C16: 3333010111 | D16: 5 | E16: Female | F16: -1970 days - 1022 days | G16: Office Visit | H16: Diabetes mellitus (EHR); Diabetic ketoacidosis (EHR); Type 1 diabetes mellitus (EHR); | S16: insulin aspart, human (day 1, for 0 days); insulin aspart, human (day 43, for 33 days); insulin aspart, human (day 118, for 76 days); insulin aspart, human (day 259, for 59 days); insulin aspart, human (day 349, for 27 days); insulin aspart, human (day 433, for 83 days); insulin aspart, human (day 553, for 389 days); insulin aspart, human (day 973, for 60 days); | U16: CASE
A17: C | C17: 4298610465 | D17: 33 | E17: Male | F17: -572 days - 3364 days | G17: Office Visit | H17: Diabetes mellitus (EHR); Type 1 diabetes mellitus (EHR); | Q17: Diabetes mellitus (day 126, 2656, 2979); Neuropathy due to diabetes mellitus (day 2445); Type 1 diabetes mellitus (day 1886) | S17: insulin, regular, human (day 22, for 27 days); insulin, regular, human (day 98, for 27 days); insulin, regular, human (day 156, for 27 days); insulin, regular, human (day 225, for 27 days); insulin, regular, human (day 311, for 55 days); insulin, regular, human (day 483, for 176 days); insulin, regular, human (day 743, for 623 days); insulin, regular, human (day 1453, for 55 days); insulin, regular, human (day 1540, for 55 days); insulin, regular, human (day 1673, for 76 days); insulin, regular, human (day 1843, for 55 days); insulin, regular, human (day 1985, for 292 days); insulin, regular, human (day 2422, for 27 days); insulin, regular, human (day 2548, for 2 days); insulin, regular, human (day 2621, for 2 days); insulin, regular, human (day 2662, for 30 days); insulin, regular, human (day 2741, for 2 days); insulin, regular, human (day 2800, for 2 days); insulin, regular, human (day 2864, for 2 days); insulin, regular, human (day 2919, for 2 days); insulin, regular, human (day 2979, for 2 days); insulin, regular, human (day 3125, for 2 days); | U17: CASE
A18: C | C18: 863610325 | D18: 23 | E18: Female | F18: -4706 days - 3281 days | G18: Office Visit | H18: Diabetic ketoacidosis (EHR); Type 1 diabetes mellitus (EHR); | S18: insulin glargine (day 7, for 0 days); insulin aspart, human (day 7, for 0 days); insulin aspart, human (day 64, for 0 days); insulin aspart, human (day 105, for 0 days); insulin glargine (day 138, for 0 days); insulin aspart, human (day 174, for 0 days); insulin aspart, human (day 228, for 0 days); insulin glargine (day 228, for 0 days); insulin aspart, human (day 307, for 0 days); insulin aspart, human (day 354, for 0 days); insulin glargine (day 354, for 0 days); insulin glargine (day 447, for 0 days); insulin aspart, human (day 447, for 0 days); insulin glargine (day 496, for 0 days); insulin aspart, human (day 496, for 0 days); insulin aspart, human (day 588, for 0 days); insulin glargine (day 650, for 0 days); insulin aspart, human (day 650, for 0 days); insulin aspart, human (day 691, for 0 days); insulin glargine (day 691, for 0 days); insulin aspart, human (day 868, for 0 days); insulin glargine (day 868, for 0 days); insulin glargine (day 1027, for 0 days); insulin aspart, human (day 1027, for 0 days); insulin glargine (day 1077, for 22 days); insulin aspart, human (day 1077, for 22 days); insulin glargine (day 1223, for 0 days); insulin aspart, human (day 1223, for 0 days); insulin aspart, human (day 1364, for 20 days); insulin glargine (day 1384, for 0 days); insulin aspart, human (day 1470, for 0 days); insulin glargine (day 1470, for 0 days); insulin aspart, human (day 1727, for 0 days); insulin glargine (day 1727, for 0 days); insulin aspart, human (day 1790, for 0 days); insulin glargine (day 1790, for 0 days); insulin aspart, human (day 1869, for 28 days); insulin glargine (day 1869, for 28 days); insulin aspart, human (day 1950, for 0 days); insulin glargine (day 1950, for 0 days); insulin aspart, human (day 2021, for 0 days); insulin glargine (day 2021, for 0 days); insulin aspart, human (day 2056, for 0 days); insulin glargine (day 2056, for 0 days); insulin aspart, human (day 2106, for 0 days); insulin glargine (day 2106, for 0 days); insulin aspart, human (day 2183, for 0 days); insulin aspart, human (day 2241, for 0 days); insulin glargine (day 2241, for 0 days); insulin aspart, human (day 2332, for 0 days); insulin glargine (day 2427, for 0 days); insulin aspart, human (day 2427, for 0 days); insulin glargine (day 2462, for 0 days); insulin aspart, human (day 2462, for 0 days); insulin aspart, human (day 2568, for 0 days); insulin glargine (day 2660, for 0 days); insulin aspart, human (day 2660, for 0 days); insulin glargine (day 2756, for 0 days); insulin aspart, human (day 2756, for 0 days); insulin glargine (day 2819, for 0 days); insulin aspart, human (day 2819, for 0 days); insulin aspart, human (day 2862, for 0 days); insulin aspart, human (day 2923, for 0 days); insulin glargine (day 2923, for 0 days); insulin glargine (day 2988, for 0 days); insulin aspart, human (day 2988, for 0 days); insulin aspart, human (day 3046, for 0 days); insulin aspart, human (day 3100, for 0 days); insulin glargine (day 3217, for 0 days); insulin aspart, human (day 3217, for 0 days); insulin aspart, human (day 3268, for 0 days); insulin glargine (day 3268, for 0 days); | U18: CASE
A19: P | C19: 3882310263 | D19: 6 | E19: Male | F19: -2146 days - 399 days | G19: Office Visit | H19: Hyperglycemia (EHR); Type 1 diabetes mellitus (EHR); | S19: insulin aspart, human (day 9, for 27 days); insulin aspart, human (day 74, for 27 days); insulin aspart, human (day 134, for 27 days); insulin aspart, human (day 212, for 69 days); insulin degludec (day 319, for 0 days); insulin aspart, human (day 351, for 27 days); insulin degludec (day 351, for 0 days); | U19: PROBABLE
A20: C | C20: 502810717 | D20: 35 | E20: Male | F20: -6642 days - 967 days | G20: Office Visit | H20: Ketoacidosis due to type 1 diabetes mellitus (EHR); Type 1 diabetes mellitus (EHR); | K20: Mixed anxiety and depressive disorder (day -5692); Recurrent depression (day -930) | S20: insulin glargine (day 6, for 101 days); insulin aspart, human (day 6, for 101 days); insulin glargine (day 147, for 211 days); insulin aspart, human (day 147, for 211 days); insulin glargine (day 392, for 0 days); insulin aspart, human (day 392, for 0 days); insulin aspart, human (day 425, for 56 days); insulin glargine (day 425, for 56 days); insulin aspart, human (day 512, for 140 days); insulin glargine (day 512, for 140 days); insulin glargine (day 685, for 27 days); insulin aspart, human (day 685, for 27 days); insulin glargine (day 748, for 0 days); insulin aspart, human (day 748, for 0 days); insulin aspart, human (day 782, for 0 days); insulin glargine (day 782, for 0 days); insulin glargine (day 825, for 0 days); insulin aspart, human (day 825, for 0 days); insulin glargine (day 870, for 0 days); insulin aspart, human (day 870, for 0 days); insulin glargine (day 910, for 27 days); insulin aspart, human (day 910, for 27 days); | U20: CASE
A21: C | C21: 811810047 | D21: 66 | E21: Male | F21: -6128 days - 302 days | G21: Office Visit | H21: Ketoacidosis due to type 1 diabetes mellitus (EHR); Type 1 diabetes mellitus (EHR); | S21: insulin glargine (day 25, for 150 days); insulin aspart, human (day 28, for 0 days); insulin aspart, human (day 63, for 0 days); insulin aspart, human (day 148, for 0 days); insulin glargine (day 206, for 69 days); insulin aspart, human (day 206, for 0 days); insulin aspart, human (day 248, for 0 days); insulin aspart, human (day 298, for 0 days); | U21: CASE
A22: C | C22: 1626210870 | D22: 4 | E22: Female | F22: -1373 days - 1158 days | G22: Office Visit | H22: Ketoacidosis due to type 1 diabetes mellitus (EHR); Type 1 diabetes mellitus (EHR); | S22: insulin glargine (day 7, for 46 days); insulin aspart, human (day 7, for 46 days); insulin aspart, human (day 160, for 27 days); insulin aspart, human (day 221, for 926 days); insulin glargine (day 221, for 309 days); | U22: CASE
A23: C | C23: 2213210607 | D23: 45 | E23: Female | F23: -5870 days - 361 days | G23: Office Visit | H23: Ketoacidosis due to type 1 diabetes mellitus (EHR); | Q23: Type 1 diabetes mellitus (day 13) | S23: insulin aspart, human (day 14, for 0 days); insulin glargine (day 14, for 0 days); insulin glargine (day 55, for 0 days); insulin aspart, human (day 55, for 0 days); insulin glargine (day 124, for 54 days); insulin aspart, human (day 154, for 24 days); insulin aspart, human (day 228, for 0 days); insulin glargine (day 242, for 0 days); insulin aspart, human (day 291, for 0 days); insulin glargine (day 291, for 0 days); insulin glargine (day 343, for 0 days); insulin aspart, human (day 343, for 0 days); | U23: CASE
A24: C | C24: 5494710200 | D24: 13 | E24: Male | F24: -4682 days - 160 days | G24: Office Visit | H24: Nocturia (EHR); Type 1 diabetes mellitus (EHR); | S24: insulin aspart, human (day 15, for 27 days); insulin degludec (day 15, for 27 days); insulin degludec (day 74, for 0 days); insulin aspart, human (day 74, for 0 days); insulin aspart, human (day 107, for 0 days); insulin degludec (day 107, for 0 days); insulin aspart, human (day 143, for 0 days); insulin degludec (day 143, for 0 days); | U24: CASE
A25: C | C25: 1525510677 | D25: 36 | E25: Male | F25: -1456 days - 7966 days | G25: Office Visit | H25: Thyrotoxicosis (EHR); Type 1 diabetes mellitus (EHR); | Q25: Diabetes mellitus (day 204); Disorder of left macula due to diabetes mellitus (day 6596); Disorder of macula due to diabetes mellitus (day 6524, 6596); Nonproliferative retinopathy due to diabetes mellitus (day 5136, 5586, 6524, 6596, 6827); Nonproliferative retinopathy of left eye due to diabetes mellitus (day 5136, 5586, 6524, 6596); Nonproliferative retinopathy of right eye due to diabetes mellitus (day 5586, 6524, 6596); Peripheral nerve disease (day 4493); Type 1 diabetes mellitus (day 245, 1184, 1227, 1281, 1342, 1609, 1771, 2051) | S25: insulin aspart, human (day 218, for 152 days); insulin aspart, human (day 413, for 0 days); insulin aspart, human (day 469, for 0 days); insulin aspart, human (day 510, for 0 days); insulin aspart, human (day 566, for 0 days); insulin aspart, human (day 621, for 0 days); insulin aspart, human (day 672, for 0 days); insulin aspart, human (day 716, for 0 days); insulin aspart, human (day 775, for 0 days); insulin aspart, human (day 819, for 0 days); insulin aspart, human (day 873, for 0 days); insulin aspart, human (day 931, for 0 days); insulin aspart, human (day 972, for 0 days); insulin aspart, human (day 1041, for 0 days); insulin aspart, human (day 1076, for 0 days); insulin aspart, human (day 1136, for 0 days); insulin aspart, human (day 1189, for 0 days); insulin aspart, human (day 1230, for 0 days); insulin aspart, human (day 1294, for 0 days); insulin aspart, human (day 1337, for 0 days); insulin aspart, human (day 1395, for 0 days); insulin aspart, human (day 1437, for 0 days); insulin aspart, human (day 1498, for 0 days); insulin aspart, human (day 1541, for 0 days); insulin aspart, human (day 1595, for 0 days); insulin aspart, human (day 1631, for 0 days); insulin aspart, human (day 1679, for 0 days); insulin aspart, human (day 1735, for 0 days); insulin aspart, human (day 1791, for 0 days); insulin aspart, human (day 1833, for 0 days); insulin aspart, human (day 1881, for 0 days); insulin aspart, human (day 1940, for 0 days); insulin aspart, human (day 1974, for 0 days); insulin aspart, human (day 2037, for 0 days); insulin aspart, human (day 2092, for 0 days); insulin aspart, human (day 2140, for 0 days); insulin aspart, human (day 2199, for 0 days); insulin aspart, human (day 2234, for 0 days); insulin aspart, human (day 2287, for 0 days); insulin aspart, human (day 2346, for 28 days); insulin aspart, human (day 2428, for 0 days); insulin aspart, human (day 2485, for 0 days); insulin aspart, human (day 2521, for 0 days); insulin aspart, human (day 2581, for 0 days); insulin aspart, human (day 2631, for 0 days); insulin aspart, human (day 2674, for 0 days); insulin aspart, human (day 2744, for 0 days); insulin aspart, human (day 2785, for 0 days); insulin aspart, human (day 2870, for 0 days); insulin aspart, human (day 2906, for 0 days); insulin aspart, human (day 2968, for 0 days); insulin aspart, human (day 3003, for 0 days); insulin aspart, human (day 3065, for 0 days); insulin aspart, human (day 3122, for 0 days); insulin aspart, human (day 3176, for 0 days); insulin aspart, human (day 3220, for 0 days); insulin aspart, human (day 3271, for 0 days); insulin aspart, human (day 3317, for 0 days); insulin aspart, human (day 3369, for 0 days); insulin aspart, human (day 3430, for 0 days); insulin aspart, human (day 3486, for 0 days); insulin aspart, human (day 3534, for 0 days); insulin aspart, human (day 3584, for 0 days); insulin aspart, human (day 3628, for 164 days); insulin glargine (day 3746, for 26 days); insulin glargine (day 3810, for 21 days); insulin aspart, human (day 3831, for 0 days); insulin glargine (day 3884, for 0 days); insulin glargine (day 3918, for 0 days); insulin aspart, human (day 3918, for 0 days); insulin glargine (day 3974, for 21 days); insulin aspart, human (day 3974, for 21 days); insulin glargine (day 4051, for 0 days); insulin aspart, human (day 4122, for 0 days); insulin aspart, human (day 4269, for 0 days); insulin aspart, human (day 4325, for 0 days); insulin aspart, human (day 4424, for 0 days); insulin aspart, human (day 4510, for 0 days); insulin aspart, human (day 4629, for 0 days); insulin aspart, human (day 4689, for 0 days); insulin aspart, human (day 4836, for 0 days); insulin aspart, human (day 4927, for 0 days); insulin aspart, human (day 5054, for 0 days); insulin aspart, human (day 5091, for 0 days); insulin aspart, human (day 5146, for 0 days); insulin aspart, human (day 5208, for 0 days); insulin aspart, human (day 5406, for 0 days); insulin aspart, human (day 5560, for 0 days); insulin aspart, human (day 5671, for 0 days); insulin aspart, human (day 5759, for 0 days); insulin aspart, human (day 5819, for 0 days); insulin aspart, human (day 5936, for 0 days); insulin aspart, human (day 6041, for 0 days); insulin aspart, human (day 6091, for 0 days); insulin aspart, human (day 6195, for 0 days); insulin aspart, human (day 6260, for 27 days); insulin aspart, human (day 6518, for 0 days); insulin aspart, human (day 6560, for 0 days); insulin aspart, human (day 6676, for 0 days); insulin aspart, human (day 6772, for 4 days); insulin aspart, human (day 6928, for 0 days); insulin aspart, human (day 7019, for 0 days); insulin glargine (day 7022, for 48 days); insulin aspart, human (day 7070, for 0 days); insulin glargine (day 7103, for 0 days); insulin glargine (day 7141, for 27 days); insulin aspart, human (day 7160, for 8 days); insulin glargine (day 7208, for 25 days); insulin glargine (day 7280, for 6 days); insulin aspart, human (day 7286, for 0 days); insulin glargine (day 7330, for 0 days); insulin aspart, human (day 7379, for 0 days); insulin glargine (day 7379, for 0 days); insulin glargine (day 7415, for 0 days); insulin aspart, human (day 7440, for 0 days); insulin glargine (day 7471, for 0 days); insulin aspart, human (day 7483, for 0 days); insulin glargine (day 7506, for 0 days); insulin glargine (day 7539, for 0 days); insulin aspart, human (day 7548, for 0 days); insulin glargine (day 7593, for 0 days); insulin aspart, human (day 7630, for 0 days); insulin glargine (day 7630, for 21 days); insulin glargine (day 7692, for 24 days); insulin aspart, human (day 7692, for 0 days); insulin aspart, human (day 7771, for 0 days); insulin glargine (day 7771, for 0 days); insulin glargine (day 7814, for 0 days); insulin aspart, human (day 7814, for 0 days); insulin aspart, human (day 7863, for 0 days); insulin glargine (day 7863, for 26 days); insulin glargine (day 7923, for 0 days); insulin aspart, human (day 7937, for 0 days); | U25: CASE
A26: C | C26: 3810766 | D26: 11 | E26: Male | F26: -2710 days - 2698 days | G26: Office Visit | H26: Type 1 diabetes mellitus (EHR); | Q26: Nonproliferative retinopathy of left eye due to diabetes mellitus (day 2465) | S26: insulin aspart, human (day 3, for 27 days); insulin, regular, human (day 3, for 1 days); insulin aspart, human (day 179, for 27 days); insulin glargine (day 213, for 0 days); insulin glargine (day 325, for 0 days); insulin aspart, human (day 403, for 27 days); insulin glargine (day 403, for 0 days); insulin glargine (day 456, for 30 days); insulin glargine (day 584, for 0 days); insulin aspart, human (day 598, for 186 days); insulin glargine (day 630, for 0 days); insulin glargine (day 672, for 0 days); insulin glargine (day 708, for 49 days); insulin glargine (day 805, for 0 days); insulin aspart, human (day 871, for 27 days); insulin glargine (day 871, for 0 days); insulin glargine (day 906, for 20 days); insulin aspart, human (day 934, for 27 days); insulin glargine (day 966, for 0 days); insulin glargine (day 1005, for 21 days); insulin aspart, human (day 1026, for 27 days); insulin glargine (day 1073, for 49 days); insulin aspart, human (day 1122, for 27 days); insulin glargine (day 1162, for 35 days); insulin aspart, human (day 1221, for 31 days); insulin glargine (day 1334, for 0 days); insulin aspart, human (day 1387, for 27 days); insulin glargine (day 1431, for 0 days); insulin glargine (day 1586, for 0 days); insulin glargine (day 1753, for 27 days); insulin aspart, human (day 1780, for 27 days); insulin glargine (day 1885, for 0 days); insulin aspart, human (day 1885, for 27 days); insulin aspart, human (day 2038, for 27 days); insulin glargine (day 2038, for 0 days); insulin aspart, human (day 2130, for 27 days); insulin glargine (day 2130, for 0 days); insulin aspart, human (day 2219, for 27 days); insulin glargine (day 2345, for 0 days); insulin aspart, human (day 2345, for 27 days); insulin glargine (day 2415, for 0 days); insulin aspart, human (day 2415, for 27 days); insulin glargine (day 2479, for 0 days); insulin aspart, human (day 2479, for 27 days); insulin glargine (day 2642, for 0 days); insulin aspart, human (day 2683, for 27 days); insulin glargine (day 2683, for 0 days); | U26: CASE
A27: N | B27: T2DM | C27: 4610438 | D27: 72 | E27: Male | F27: -7344 days - 1896 days | G27: Office Visit | H27: Type 1 diabetes mellitus (EHR); Type 2 diabetes mellitus (EHR); | K27: Chronic kidney disease stage 3A (day -379) | Q27: Carpal tunnel syndrome (day 1788); Chronic kidney disease stage 3B (day 175) | S27: insulin aspart, human (day 3, for 0 days); insulin glargine (day 41, for 27 days); insulin aspart, human (day 41, for 27 days); insulin aspart, human (day 160, for 49 days); insulin glargine (day 160, for 49 days); insulin glargine (day 461, for 27 days); insulin glargine (day 577, for 27 days); insulin aspart, human (day 681, for 27 days); insulin glargine (day 681, for 27 days); insulin aspart, human (day 794, for 27 days); insulin glargine (day 794, for 27 days); insulin glargine (day 864, for 27 days); insulin glargine (day 941, for 27 days); insulin glargine (day 1018, for 27 days); insulin glargine (day 1122, for 27 days); insulin glargine (day 1204, for 27 days); insulin glargine (day 1277, for 27 days); insulin glargine (day 1351, for 27 days); insulin glargine (day 1434, for 27 days); insulin glargine (day 1533, for 27 days); insulin glargine (day 1613, for 27 days); insulin glargine (day 1697, for 79 days); insulin glargine (day 1827, for 27 days); insulin aspart, human (day 1833, for 0 days); | U27: NON-CASE | V27: Likely index date misclassification (TD2M)
